Workbook

Sheet Summary
A1: KINETIC REVENUE MODEL | C1: Generated April 12, 2026 16:14
A2: Ticker | B2: Beat % | C2: Momentum | D2: Q1-24 | E2: Q2-24 | F2: Q3-24 | G2: Q4-24 | H2: FY24 | I2: Q1-25 | J2: Q2-25 | K2: Q3-25 | L2: Q4-25 | M2: FY25 | N2: Q1-26 | O2: Q2-26E | P2: Q3-26E | Q2: Q4-26E | R2: FY26E | S2: Q1-27E | T2: Q2-27E | U2: Q3-27E | V2: Q4-27E | W2: FY27E | X2: Q1-28E | Z2: Impl Guide | AA2: Consensus | AB2: Gap %
A3: Total Revenue ($M)
A4: ADBE | B4: 0.0144 | C4: STABLE | D4: ='ADBE'!D9 | E4: ='ADBE'!E9 | F4: ='ADBE'!F9 | G4: ='ADBE'!G9 | H4: ='ADBE'!H9 | I4: ='ADBE'!I9 | J4: ='ADBE'!J9 | K4: ='ADBE'!K9 | ... W4: ='ADBE'!W9 | Z4: ='ADBE'!P23 | AA4: ='ADBE'!P15 | AB4: =IFERROR((Z4-AA4)/AA4,"-")
A5: INTU | B5: 0.0271 | C5: ACCELERATING | D5: ='INTU'!D9 | E5: ='INTU'!E9 | F5: ='INTU'!F9 | G5: ='INTU'!G9 | H5: ='INTU'!H9 | I5: ='INTU'!I9 | J5: ='INTU'!J9 | K5: ='INTU'!K9 | ... X5: ='INTU'!X9 | Z5: ='INTU'!P23 | AA5: ='INTU'!P15 | AB5: =IFERROR((Z5-AA5)/AA5,"-")
A6: NOW | B6: 0.0111 | C6: STABLE | D6: ='NOW'!D9 | E6: ='NOW'!E9 | F6: ='NOW'!F9 | G6: ='NOW'!G9 | H6: ='NOW'!H9 | I6: ='NOW'!I9 | J6: ='NOW'!J9 | K6: ='NOW'!K9 | ... W6: ='NOW'!W9 | Z6: ='NOW'!O23 | AA6: ='NOW'!O15 | AB6: =IFERROR((Z6-AA6)/AA6,"-")
A7: PANW | B7: 0.0077 | C7: STABLE | D7: ='PANW'!D9 | E7: ='PANW'!E9 | F7: ='PANW'!F9 | G7: ='PANW'!G9 | H7: ='PANW'!H9 | I7: ='PANW'!I9 | J7: ='PANW'!J9 | K7: ='PANW'!K9 | ... X7: ='PANW'!X9 | Z7: ='PANW'!P23 | AA7: ='PANW'!P15 | AB7: =IFERROR((Z7-AA7)/AA7,"-")
A8: WDAY | B8: 0.0046 | C8: STABLE | D8: ='WDAY'!D9 | E8: ='WDAY'!E9 | F8: ='WDAY'!F9 | G8: ='WDAY'!G9 | H8: ='WDAY'!H9 | I8: ='WDAY'!I9 | J8: ='WDAY'!J9 | K8: ='WDAY'!K9 | ... X8: ='WDAY'!X9 | Z8: ='WDAY'!P23 | AA8: ='WDAY'!P15 | AB8: =IFERROR((Z8-AA8)/AA8,"-")
A9: SNPS | B9: 0.002 | C9: STABLE | D9: ='SNPS'!D9 | E9: ='SNPS'!E9 | F9: ='SNPS'!F9 | G9: ='SNPS'!G9 | H9: ='SNPS'!H9 | I9: ='SNPS'!I9 | J9: ='SNPS'!J9 | K9: ='SNPS'!K9 | ... X9: ='SNPS'!X9 | Z9: ='SNPS'!P23 | AA9: ='SNPS'!P15 | AB9: =IFERROR((Z9-AA9)/AA9,"-")
A10: ROP | B10: -0.0012 | C10: STABLE | D10: ='ROP'!D9 | E10: ='ROP'!E9 | F10: ='ROP'!F9 | G10: ='ROP'!G9 | H10: ='ROP'!H9 | I10: ='ROP'!I9 | J10: ='ROP'!J9 | K10: ='ROP'!K9 | ... W10: ='ROP'!W9 | Z10: ='ROP'!O23 | AA10: ='ROP'!O15 | AB10: =IFERROR((Z10-AA10)/AA10,"-")
A11: ADSK | B11: 0.0204 | C11: STABLE | D11: ='ADSK'!D9 | E11: ='ADSK'!E9 | F11: ='ADSK'!F9 | G11: ='ADSK'!G9 | H11: ='ADSK'!H9 | I11: ='ADSK'!I9 | J11: ='ADSK'!J9 | K11: ='ADSK'!K9 | ... X11: ='ADSK'!X9 | Z11: ='ADSK'!P23 | AA11: ='ADSK'!P15 | AB11: =IFERROR((Z11-AA11)/AA11,"-")
A12: FTNT | B12: 0.0101 | C12: ACCELERATING | D12: ='FTNT'!D9 | E12: ='FTNT'!E9 | F12: ='FTNT'!F9 | G12: ='FTNT'!G9 | H12: ='FTNT'!H9 | I12: ='FTNT'!I9 | J12: ='FTNT'!J9 | K12: ='FTNT'!K9 | ... W12: ='FTNT'!W9 | Z12: ='FTNT'!O23 | AA12: ='FTNT'!O15 | AB12: =IFERROR((Z12-AA12)/AA12,"-")
A13: TOST | B13: 0.0156 | C13: DECELERATING | D13: ='TOST'!D9 | E13: ='TOST'!E9 | F13: ='TOST'!F9 | G13: ='TOST'!G9 | H13: ='TOST'!H9 | I13: ='TOST'!I9 | J13: ='TOST'!J9 | K13: ='TOST'!K9 | ... W13: ='TOST'!W9 | Z13: ='TOST'!O23 | AA13: ='TOST'!O15 | AB13: =IFERROR((Z13-AA13)/AA13,"-")
A14: TEAM | B14: 0.0159 | C14: ACCELERATING | D14: ='TEAM'!D9 | E14: ='TEAM'!E9 | F14: ='TEAM'!F9 | G14: ='TEAM'!G9 | H14: ='TEAM'!H9 | I14: ='TEAM'!I9 | J14: ='TEAM'!J9 | K14: ='TEAM'!K9 | ... W14: ='TEAM'!W9 | Z14: ='TEAM'!O23 | AA14: ='TEAM'!O15 | AB14: =IFERROR((Z14-AA14)/AA14,"-")
A15: APP | B15: 0.0445 | C15: STABLE | D15: ='APP'!D9 | E15: ='APP'!E9 | F15: ='APP'!F9 | G15: ='APP'!G9 | H15: ='APP'!H9 | I15: ='APP'!I9 | J15: ='APP'!J9 | K15: ='APP'!K9 | ... W15: ='APP'!W9 | Z15: ='APP'!O23 | AA15: ='APP'!O15 | AB15: =IFERROR((Z15-AA15)/AA15,"-")
A16: CDNS | B16: 0.0115 | C16: ACCELERATING | D16: ='CDNS'!D9 | E16: ='CDNS'!E9 | F16: ='CDNS'!F9 | G16: ='CDNS'!G9 | H16: ='CDNS'!H9 | I16: ='CDNS'!I9 | J16: ='CDNS'!J9 | K16: ='CDNS'!K9 | ... W16: ='CDNS'!W9 | Z16: ='CDNS'!O23 | AA16: ='CDNS'!O15 | AB16: =IFERROR((Z16-AA16)/AA16,"-")
A17: CRWD | B17: 0.0094 | C17: STABLE | D17: ='CRWD'!D9 | E17: ='CRWD'!E9 | F17: ='CRWD'!F9 | G17: ='CRWD'!G9 | H17: ='CRWD'!H9 | I17: ='CRWD'!I9 | J17: ='CRWD'!J9 | K17: ='CRWD'!K9 | ... X17: ='CRWD'!X9 | Z17: ='CRWD'!P23 | AA17: ='CRWD'!P15 | AB17: =IFERROR((Z17-AA17)/AA17,"-")
A18: SNOW | B18: 0.0352 | C18: STABLE | D18: ='SNOW'!D9 | E18: ='SNOW'!E9 | F18: ='SNOW'!F9 | G18: ='SNOW'!G9 | H18: ='SNOW'!H9 | I18: ='SNOW'!I9 | J18: ='SNOW'!J9 | K18: ='SNOW'!K9 | ... X18: ='SNOW'!X9 | Z18: ='SNOW'!P23 | AA18: ='SNOW'!P15 | AB18: =IFERROR((Z18-AA18)/AA18,"-")
A19: PLTR | B19: 0.0566 | C19: ACCELERATING | D19: ='PLTR'!D9 | E19: ='PLTR'!E9 | F19: ='PLTR'!F9 | G19: ='PLTR'!G9 | H19: ='PLTR'!H9 | I19: ='PLTR'!I9 | J19: ='PLTR'!J9 | K19: ='PLTR'!K9 | ... W19: ='PLTR'!W9 | Z19: ='PLTR'!O23 | AA19: ='PLTR'!O15 | AB19: =IFERROR((Z19-AA19)/AA19,"-")
A20: DDOG | B20: 0.0349 | C20: STABLE | D20: ='DDOG'!D9 | E20: ='DDOG'!E9 | F20: ='DDOG'!F9 | G20: ='DDOG'!G9 | H20: ='DDOG'!H9 | I20: ='DDOG'!I9 | J20: ='DDOG'!J9 | K20: ='DDOG'!K9 | ... W20: ='DDOG'!W9 | Z20: ='DDOG'!O23 | AA20: ='DDOG'!O15 | AB20: =IFERROR((Z20-AA20)/AA20,"-")
A21: VEEV | B21: 0.0281 | C21: STABLE | D21: ='VEEV'!D9 | E21: ='VEEV'!E9 | F21: ='VEEV'!F9 | G21: ='VEEV'!G9 | H21: ='VEEV'!H9 | I21: ='VEEV'!I9 | J21: ='VEEV'!J9 | K21: ='VEEV'!K9 | ... X21: ='VEEV'!X9 | Z21: ='VEEV'!P23 | AA21: ='VEEV'!P15 | AB21: =IFERROR((Z21-AA21)/AA21,"-")
A22: HUBS | B22: 0.0238 | C22: STABLE | D22: ='HUBS'!D9 | E22: ='HUBS'!E9 | F22: ='HUBS'!F9 | G22: ='HUBS'!G9 | H22: ='HUBS'!H9 | I22: ='HUBS'!I9 | J22: ='HUBS'!J9 | K22: ='HUBS'!K9 | ... W22: ='HUBS'!W9 | Z22: ='HUBS'!O23 | AA22: ='HUBS'!O15 | AB22: =IFERROR((Z22-AA22)/AA22,"-")
A23: ZS | B23: 0.019 | C23: STABLE | D23: ='ZS'!D9 | E23: ='ZS'!E9 | F23: ='ZS'!F9 | G23: ='ZS'!G9 | H23: ='ZS'!H9 | I23: ='ZS'!I9 | J23: ='ZS'!J9 | K23: ='ZS'!K9 | ... X23: ='ZS'!X9 | Z23: ='ZS'!P23 | AA23: ='ZS'!P15 | AB23: =IFERROR((Z23-AA23)/AA23,"-")
A24: OKTA | B24: 0.0187 | C24: STABLE | D24: ='OKTA'!D9 | E24: ='OKTA'!E9 | F24: ='OKTA'!F9 | G24: ='OKTA'!G9 | H24: ='OKTA'!H9 | I24: ='OKTA'!I9 | J24: ='OKTA'!J9 | K24: ='OKTA'!K9 | ... X24: ='OKTA'!X9 | Z24: ='OKTA'!P23 | AA24: ='OKTA'!P15 | AB24: =IFERROR((Z24-AA24)/AA24,"-")
A25: TTD | B25: 0.0178 | C25: STABLE | D25: ='TTD'!D9 | E25: ='TTD'!E9 | F25: ='TTD'!F9 | G25: ='TTD'!G9 | H25: ='TTD'!H9 | I25: ='TTD'!I9 | J25: ='TTD'!J9 | K25: ='TTD'!K9 | ... W25: ='TTD'!W9 | Z25: ='TTD'!O23 | AA25: ='TTD'!O15 | AB25: =IFERROR((Z25-AA25)/AA25,"-")
A26: MDB | B26: 0.0505 | C26: STABLE | D26: ='MDB'!D9 | E26: ='MDB'!E9 | F26: ='MDB'!F9 | G26: ='MDB'!G9 | H26: ='MDB'!H9 | I26: ='MDB'!I9 | J26: ='MDB'!J9 | K26: ='MDB'!K9 | ... X26: ='MDB'!X9 | Z26: ='MDB'!P23 | AA26: ='MDB'!P15 | AB26: =IFERROR((Z26-AA26)/AA26,"-")
A27: PAYC | B27: 0.0095 | C27: ACCELERATING | D27: ='PAYC'!D9 | E27: ='PAYC'!E9 | F27: ='PAYC'!F9 | G27: ='PAYC'!G9 | H27: ='PAYC'!H9 | I27: ='PAYC'!I9 | J27: ='PAYC'!J9 | K27: ='PAYC'!K9 | ... W27: ='PAYC'!W9 | Z27: ='PAYC'!O23 | AA27: ='PAYC'!O15 | AB27: =IFERROR((Z27-AA27)/AA27,"-")
A28: DT | B28: 0.0194 | C28: STABLE | D28: ='DT'!D9 | E28: ='DT'!E9 | F28: ='DT'!F9 | G28: ='DT'!G9 | H28: ='DT'!H9 | I28: ='DT'!I9 | J28: ='DT'!J9 | K28: ='DT'!K9 | ... W28: ='DT'!W9 | Z28: ='DT'!O23 | AA28: ='DT'!O15 | AB28: =IFERROR((Z28-AA28)/AA28,"-")
A29: PCTY | B29: 0.0216 | C29: STABLE | D29: ='PCTY'!D9 | E29: ='PCTY'!E9 | F29: ='PCTY'!F9 | G29: ='PCTY'!G9 | H29: ='PCTY'!H9 | I29: ='PCTY'!I9 | J29: ='PCTY'!J9 | K29: ='PCTY'!K9 | ... W29: ='PCTY'!W9 | Z29: ='PCTY'!O23 | AA29: ='PCTY'!O15 | AB29: =IFERROR((Z29-AA29)/AA29,"-")
A30: ESTC | B30: 0.0244 | C30: STABLE | D30: ='ESTC'!D9 | E30: ='ESTC'!E9 | F30: ='ESTC'!F9 | G30: ='ESTC'!G9 | H30: ='ESTC'!H9 | I30: ='ESTC'!I9 | J30: ='ESTC'!J9 | K30: ='ESTC'!K9 | ... X30: ='ESTC'!X9 | Z30: ='ESTC'!P23 | AA30: ='ESTC'!P15 | AB30: =IFERROR((Z30-AA30)/AA30,"-")
A31: BILL | B31: 0.008 | C31: STABLE | D31: ='BILL'!D9 | E31: ='BILL'!E9 | F31: ='BILL'!F9 | G31: ='BILL'!G9 | H31: ='BILL'!H9 | I31: ='BILL'!I9 | J31: ='BILL'!J9 | K31: ='BILL'!K9 | ... W31: ='BILL'!W9 | Z31: ='BILL'!O23 | AA31: ='BILL'!O15 | AB31: =IFERROR((Z31-AA31)/AA31,"-")
A32: BSY | B32: 0.0135 | C32: ACCELERATING | D32: ='BSY'!D9 | E32: ='BSY'!E9 | F32: ='BSY'!F9 | G32: ='BSY'!G9 | H32: ='BSY'!H9 | I32: ='BSY'!I9 | J32: ='BSY'!J9 | K32: ='BSY'!K9 | ... W32: ='BSY'!W9 | Z32: ='BSY'!O23 | AA32: ='BSY'!O15 | AB32: =IFERROR((Z32-AA32)/AA32,"-")
A33: GWRE | B33: 0.0447 | C33: STABLE | D33: ='GWRE'!D9 | E33: ='GWRE'!E9 | F33: ='GWRE'!F9 | G33: ='GWRE'!G9 | H33: ='GWRE'!H9 | I33: ='GWRE'!I9 | J33: ='GWRE'!J9 | K33: ='GWRE'!K9 | ... X33: ='GWRE'!X9 | Z33: ='GWRE'!P23 | AA33: ='GWRE'!P15 | AB33: =IFERROR((Z33-AA33)/AA33,"-")
A34: PCOR | B34: 0.0174 | C34: STABLE | D34: ='PCOR'!D9 | E34: ='PCOR'!E9 | F34: ='PCOR'!F9 | G34: ='PCOR'!G9 | H34: ='PCOR'!H9 | I34: ='PCOR'!I9 | J34: ='PCOR'!J9 | K34: ='PCOR'!K9 | ... W34: ='PCOR'!W9 | Z34: ='PCOR'!O23 | AA34: ='PCOR'!O15 | AB34: =IFERROR((Z34-AA34)/AA34,"-")
A35: ZI | B35: 0.0304 | C35: STABLE | D35: ='ZI'!D9 | E35: ='ZI'!E9 | F35: ='ZI'!F9 | G35: ='ZI'!G9 | H35: ='ZI'!H9 | I35: ='ZI'!I9 | J35: ='ZI'!J9 | K35: ='ZI'!K9 | ... W35: ='ZI'!W9 | Z35: ='ZI'!O23 | AA35: ='ZI'!O15 | AB35: =IFERROR((Z35-AA35)/AA35,"-")
A36: KVYO | B36: 0.045 | C36: ACCELERATING | D36: ='KVYO'!D9 | E36: ='KVYO'!E9 | F36: ='KVYO'!F9 | G36: ='KVYO'!G9 | H36: ='KVYO'!H9 | I36: ='KVYO'!I9 | J36: ='KVYO'!J9 | K36: ='KVYO'!K9 | ... W36: ='KVYO'!W9 | Z36: ='KVYO'!O23 | AA36: ='KVYO'!O15 | AB36: =IFERROR((Z36-AA36)/AA36,"-")
A37: MNDY | B37: 0.0166 | C37: STABLE | D37: ='MNDY'!D9 | E37: ='MNDY'!E9 | F37: ='MNDY'!F9 | G37: ='MNDY'!G9 | H37: ='MNDY'!H9 | I37: ='MNDY'!I9 | J37: ='MNDY'!J9 | K37: ='MNDY'!K9 | ... W37: ='MNDY'!W9 | Z37: ='MNDY'!O23 | AA37: ='MNDY'!O15 | AB37: =IFERROR((Z37-AA37)/AA37,"-")
A38: CFLT | B38: 0.0026 | C38: ACCELERATING | D38: ='CFLT'!D9 | E38: ='CFLT'!E9 | F38: ='CFLT'!F9 | G38: ='CFLT'!G9 | H38: ='CFLT'!H9 | I38: ='CFLT'!I9 | J38: ='CFLT'!J9 | K38: ='CFLT'!K9 | ... W38: ='CFLT'!W9 | Z38: ='CFLT'!O23 | AA38: ='CFLT'!O15 | AB38: =IFERROR((Z38-AA38)/AA38,"-")
A39: AZPN | B39: 0.0087 | C39: STABLE | D39: ='AZPN'!I9 | E39: ='AZPN'!J9 | F39: ='AZPN'!K9 | G39: ='AZPN'!L9 | H39: ='AZPN'!M9 | I39: ='AZPN'!N9 | J39: ='AZPN'!O9 | K39: ='AZPN'!P9 | ... W39: ='AZPN'!AB9 | Z39: ='AZPN'!O23 | AA39: ='AZPN'!O15 | AB39: =IFERROR((Z39-AA39)/AA39,"-")
A40: MANH | B40: 0.0234 | C40: DECELERATING | D40: ='MANH'!D9 | E40: ='MANH'!E9 | F40: ='MANH'!F9 | G40: ='MANH'!G9 | H40: ='MANH'!H9 | I40: ='MANH'!I9 | J40: ='MANH'!J9 | K40: ='MANH'!K9 | ... W40: ='MANH'!W9 | Z40: ='MANH'!O23 | AA40: ='MANH'!O15 | AB40: =IFERROR((Z40-AA40)/AA40,"-")
...

Sheet SNOW
B1: SNOW: KIN Base Case Operating Model
B2: USD in Millions Unless Stated Otherwise
B3: Beat Cadence (%) | C3: 0.0352
B4: Beat Window | C4: 8Q
B5: Momentum | C5: STABLE
D7: Q1-24 | E7: Q2-24 | F7: Q3-24 | G7: Q4-24 | H7: FY24 | I7: Q1-25 | J7: Q2-25 | K7: Q3-25 | L7: Q4-25 | M7: FY25 | N7: Q1-26 | O7: Q2-26E | P7: Q3-26E | Q7: Q4-26E | R7: FY26E | S7: Q1-27E | T7: Q2-27E | U7: Q3-27E | V7: Q4-27E | W7: FY27E | X7: Q1-28E
B9: Total Revenue | D9: 774.699 | E9: 828.709 | F9: 868.823 | G9: 942.094 | H9: =SUM(D9:G9) | I9: 986.77 | J9: 1042.074 | K9: 1144.969 | L9: 1212.909 | M9: =SUM(I9:L9) | N9: 1283.994 | O9: =N9+O13 | P9: =O9+P13 | Q9: =P9+Q13 | R9: =SUM(N9:Q9) | S9: =Q9+S13 | T9: =S9+T13 | U9: =T9+U13 | V9: =U9+V13 | W9: =SUM(S9:V9) | X9: =V9+X13
B10: % YoY | I10: =IFERROR((I9-D9)/D9,"-") | J10: =IFERROR((J9-E9)/E9,"-") | K10: =IFERROR((K9-F9)/F9,"-") | L10: =IFERROR((L9-G9)/G9,"-") | M10: =IFERROR((M9-H9)/H9,"-") | N10: =IFERROR((N9-I9)/I9,"-") | O10: =IFERROR((O9-J9)/J9,"-") | P10: =IFERROR((P9-K9)/K9,"-") | ... X10: =IFERROR((X9-S9)/S9,"-")
B11: % QoQ | E11: =IFERROR((E9-D9)/D9,"-") | F11: =IFERROR((F9-E9)/E9,"-") | G11: =IFERROR((G9-F9)/F9,"-") | I11: =IFERROR((I9-G9)/G9,"-") | J11: =IFERROR((J9-I9)/I9,"-") | K11: =IFERROR((K9-J9)/J9,"-") | L11: =IFERROR((L9-K9)/K9,"-") | N11: =IFERROR((N9-L9)/L9,"-") | O11: =IFERROR((O9-N9)/N9,"-") | P11: =IFERROR((P9-O9)/O9,"-") | Q11: =IFERROR((Q9-P9)/P9,"-") | S11: =IFERROR((S9-Q9)/Q9,"-") | T11: =IFERROR((T9-S9)/S9,"-") | U11: =IFERROR((U9-T9)/T9,"-") | V11: =IFERROR((V9-U9)/U9,"-") | X11: =IFERROR((X9-V9)/V9,"-")
B12: $ YoY | I12: =I9-D9 | J12: =J9-E9 | K12: =K9-F9 | L12: =L9-G9 | M12: =M9-H9 | N12: =N9-I9 | O12: =O9-J9 | P12: =P9-K9 | ... X12: =X9-S9
B13: $ QoQ | E13: =E9-D9 | F13: =F9-E9 | G13: =G9-F9 | I13: =I9-G9 | J13: =J9-I9 | K13: =K9-J9 | L13: =L9-K9 | N13: =N9-L9 | O13: 78.569223 | P13: 57.632653 | Q13: 73.878316 | S13: 75.776472 | T13: 80.056524 | U13: 76.922439 | V13: 82.482094 | X13: 86.472586
B15: Consensus Total Revenue | O15: 1316.2319 | P15: 1446.1974 | Q15: 1531.388 | S15: 1620.3051 | T15: 1654.7962 | U15: 1777.674 | V15: 1886.2974 | W15: =SUM(S15:V15) | X15: 1982.0605
B16: % YoY | T16: =IFERROR((T15-O15)/O15,"-") | U16: =IFERROR((U15-P15)/P15,"-") | V16: =IFERROR((V15-Q15)/Q15,"-") | X16: =IFERROR((X15-S15)/S15,"-")
B17: % QoQ | P17: =IFERROR((P15-O15)/O15,"-") | Q17: =IFERROR((Q15-P15)/P15,"-") | S17: =IFERROR((S15-Q15)/Q15,"-") | T17: =IFERROR((T15-S15)/S15,"-") | U17: =IFERROR((U15-T15)/T15,"-") | V17: =IFERROR((V15-U15)/U15,"-") | X17: =IFERROR((X15-V15)/V15,"-")
B18: $ YoY | T18: =T15-O15 | U18: =U15-P15 | V18: =V15-Q15 | X18: =X15-S15
B19: $ QoQ | P19: =P15-O15 | Q19: =Q15-P15 | S19: =S15-Q15 | T19: =T15-S15 | U19: =U15-T15 | V19: =V15-U15 | X19: =X15-V15
B21: % Variance vs Consensus | O21: =IFERROR((O9-O15)/O15,"-") | P21: =IFERROR((P9-P15)/P15,"-") | Q21: =IFERROR((Q9-Q15)/Q15,"-") | R21: =IFERROR((R9-R15)/R15,"-") | S21: =IFERROR((S9-S15)/S15,"-") | T21: =IFERROR((T9-T15)/T15,"-") | U21: =IFERROR((U9-U15)/U15,"-") | V21: =IFERROR((V9-V15)/V15,"-") | ... X21: =IFERROR((X9-X15)/X15,"-")
B23: Implied Q+2 Guide | P23: =P9/(1+$C$3)
B24: % YoY | P24: =IFERROR((P23-K9)/K9,"-")
B25: % QoQ | P25: =IFERROR((P23-O9)/O9,"-")
B26: $ YoY | P26: =P23-K9
B27: $ QoQ | P27: =P23-O9
B29: % Variance Guide vs Consensus | P29: =IFERROR((P23-P15)/P15,"-")
B31: Actuals vs Consensus
B32: Actual Revenue | D32: 774.699 | E32: 828.709 | F32: 868.823 | G32: 942.094 | H32: =SUM(D32:G32) | I32: 986.77 | J32: 1042.074 | K32: 1144.969 | L32: 1212.909 | M32: =SUM(I32:L32) | N32: 1283.994
B33: Consensus Revenue | D33: 760.43181 | E33: 788.103 | F33: 853.11178 | G33: 899.30699 | H33: =SUM(D33:G33) | I33: 957.78921 | J33: 1006.2994 | K33: 1088.0741 | L33: 1184.3406 | M33: =SUM(I33:L33) | N33: 1256.722
B34: Beat / Miss ($) | D34: =D32-D33 | E34: =E32-E33 | F34: =F32-F33 | G34: =G32-G33 | H34: =H32-H33 | I34: =I32-I33 | J34: =J32-J33 | K34: =K32-K33 | ... N34: =N32-N33
B35: Beat / Miss (%) | D35: =IFERROR((D32-D33)/D33,"-") | E35: =IFERROR((E32-E33)/E33,"-") | F35: =IFERROR((F32-F33)/F33,"-") | G35: =IFERROR((G32-G33)/G33,"-") | H35: =IFERROR((H32-H33)/H33,"-") | I35: =IFERROR((I32-I33)/I33,"-") | J35: =IFERROR((J32-J33)/J33,"-") | K35: =IFERROR((K32-K33)/K33,"-") | ... N35: =IFERROR((N32-N33)/N33,"-")
B37: Trailing 4Q Avg Beat | C37: =AVERAGE(J35,K35,L35,N35)
B38: Trailing 8Q Avg Beat | C38: =AVERAGE(E35,F35,G35,I35,J35,K35,L35,N35)
B39: Selected Beat Cadence | C39: 0.0352

Sheet DDOG
B1: DDOG: KIN Base Case Operating Model
B2: USD in Millions Unless Stated Otherwise
B3: Beat Cadence (%) | C3: 0.0349
B4: Beat Window | C4: 8Q
B5: Momentum | C5: STABLE
D7: Q1-24 | E7: Q2-24 | F7: Q3-24 | G7: Q4-24 | H7: FY24 | I7: Q1-25 | J7: Q2-25 | K7: Q3-25 | L7: Q4-25 | M7: FY25 | N7: Q1-26E | O7: Q2-26E | P7: Q3-26E | Q7: Q4-26E | R7: FY26E | S7: Q1-27E | T7: Q2-27E | U7: Q3-27E | V7: Q4-27E | W7: FY27E
B9: Total Revenue | D9: 611.253 | E9: 645.279 | F9: 690.016 | G9: 737.727 | H9: =SUM(D9:G9) | I9: 761.553 | J9: 826.76 | K9: 885.651 | L9: 953.194 | M9: =SUM(I9:L9) | N9: =L9+N13 | O9: =N9+O13 | P9: =O9+P13 | Q9: =P9+Q13 | R9: =SUM(N9:Q9) | S9: =Q9+S13 | T9: =S9+T13 | U9: =T9+U13 | V9: =U9+V13 | W9: =SUM(S9:V9)
B10: % YoY | I10: =IFERROR((I9-D9)/D9,"-") | J10: =IFERROR((J9-E9)/E9,"-") | K10: =IFERROR((K9-F9)/F9,"-") | L10: =IFERROR((L9-G9)/G9,"-") | M10: =IFERROR((M9-H9)/H9,"-") | N10: =IFERROR((N9-I9)/I9,"-") | O10: =IFERROR((O9-J9)/J9,"-") | P10: =IFERROR((P9-K9)/K9,"-") | ... W10: =IFERROR((W9-R9)/R9,"-")
B11: % QoQ | E11: =IFERROR((E9-D9)/D9,"-") | F11: =IFERROR((F9-E9)/E9,"-") | G11: =IFERROR((G9-F9)/F9,"-") | I11: =IFERROR((I9-G9)/G9,"-") | J11: =IFERROR((J9-I9)/I9,"-") | K11: =IFERROR((K9-J9)/J9,"-") | L11: =IFERROR((L9-K9)/K9,"-") | N11: =IFERROR((N9-L9)/L9,"-") | O11: =IFERROR((O9-N9)/N9,"-") | P11: =IFERROR((P9-O9)/O9,"-") | Q11: =IFERROR((Q9-P9)/P9,"-") | S11: =IFERROR((S9-Q9)/Q9,"-") | T11: =IFERROR((T9-S9)/S9,"-") | U11: =IFERROR((U9-T9)/T9,"-") | V11: =IFERROR((V9-U9)/U9,"-")
B12: $ YoY | I12: =I9-D9 | J12: =J9-E9 | K12: =K9-F9 | L12: =L9-G9 | M12: =M9-H9 | N12: =N9-I9 | O12: =O9-J9 | P12: =P9-K9 | ... W12: =W9-R9
B13: $ QoQ | E13: =E9-D9 | F13: =F9-E9 | G13: =G9-F9 | I13: =I9-G9 | J13: =J9-I9 | K13: =K9-J9 | L13: =L9-K9 | N13: 36.1704 | O13: 32.854789 | P13: 59.307231 | Q13: 64.292587 | S13: 40.352753 | T13: 54.271897 | U13: 60.658508 | V13: 66.764154
B15: Consensus Total Revenue | N15: 956 | O15: 992.56722 | P15: 1047.1315 | Q15: 1112.3427 | R15: =SUM(N15:Q15) | S15: 1141.0986 | T15: 1182.0816 | U15: 1246.3868 | V15: 1326.5623 | W15: =SUM(S15:V15)
B16: % YoY | S16: =IFERROR((S15-N15)/N15,"-") | T16: =IFERROR((T15-O15)/O15,"-") | U16: =IFERROR((U15-P15)/P15,"-") | V16: =IFERROR((V15-Q15)/Q15,"-") | W16: =IFERROR((W15-R15)/R15,"-")
B17: % QoQ | O17: =IFERROR((O15-N15)/N15,"-") | P17: =IFERROR((P15-O15)/O15,"-") | Q17: =IFERROR((Q15-P15)/P15,"-") | S17: =IFERROR((S15-Q15)/Q15,"-") | T17: =IFERROR((T15-S15)/S15,"-") | U17: =IFERROR((U15-T15)/T15,"-") | V17: =IFERROR((V15-U15)/U15,"-")
B18: $ YoY | S18: =S15-N15 | T18: =T15-O15 | U18: =U15-P15 | V18: =V15-Q15 | W18: =W15-R15
B19: $ QoQ | O19: =O15-N15 | P19: =P15-O15 | Q19: =Q15-P15 | S19: =S15-Q15 | T19: =T15-S15 | U19: =U15-T15 | V19: =V15-U15
B21: % Variance vs Consensus | N21: =IFERROR((N9-N15)/N15,"-") | O21: =IFERROR((O9-O15)/O15,"-") | P21: =IFERROR((P9-P15)/P15,"-") | Q21: =IFERROR((Q9-Q15)/Q15,"-") | R21: =IFERROR((R9-R15)/R15,"-") | S21: =IFERROR((S9-S15)/S15,"-") | T21: =IFERROR((T9-T15)/T15,"-") | U21: =IFERROR((U9-U15)/U15,"-") | ... W21: =IFERROR((W9-W15)/W15,"-")
B23: Implied Q+2 Guide | O23: =O9/(1+$C$3)
B24: % YoY | O24: =IFERROR((O23-J9)/J9,"-")
B25: % QoQ | O25: =IFERROR((O23-N9)/N9,"-")
B26: $ YoY | O26: =O23-J9
B27: $ QoQ | O27: =O23-N9
B29: % Variance Guide vs Consensus | O29: =IFERROR((O23-O15)/O15,"-")
B31: Actuals vs Consensus
B32: Actual Revenue | D32: 611.253 | E32: 645.279 | F32: 690.016 | G32: 737.727 | H32: =SUM(D32:G32) | I32: 761.553 | J32: 826.76 | K32: 885.651 | L32: 953.194 | M32: =SUM(I32:L32)
B33: Consensus Revenue | D33: 592.03185 | E33: 626.89173 | F33: 665.04114 | G33: 715.17878 | H33: =SUM(D33:G33) | I33: 741.41308 | J33: 791.12383 | K33: 852.76166 | L33: 918.7008 | M33: =SUM(I33:L33)
B34: Beat / Miss ($) | D34: =D32-D33 | E34: =E32-E33 | F34: =F32-F33 | G34: =G32-G33 | H34: =H32-H33 | I34: =I32-I33 | J34: =J32-J33 | K34: =K32-K33 | ... M34: =M32-M33
B35: Beat / Miss (%) | D35: =IFERROR((D32-D33)/D33,"-") | E35: =IFERROR((E32-E33)/E33,"-") | F35: =IFERROR((F32-F33)/F33,"-") | G35: =IFERROR((G32-G33)/G33,"-") | H35: =IFERROR((H32-H33)/H33,"-") | I35: =IFERROR((I32-I33)/I33,"-") | J35: =IFERROR((J32-J33)/J33,"-") | K35: =IFERROR((K32-K33)/K33,"-") | ... M35: =IFERROR((M32-M33)/M33,"-")
B37: Trailing 4Q Avg Beat | C37: =AVERAGE(I35,J35,K35,L35)
B38: Trailing 8Q Avg Beat | C38: =AVERAGE(D35,E35,F35,G35,I35,J35,K35,L35)
B39: Selected Beat Cadence | C39: 0.0349

Sheet MDB
B1: MDB: KIN Base Case Operating Model
B2: USD in Millions Unless Stated Otherwise
B3: Beat Cadence (%) | C3: 0.0505
B4: Beat Window | C4: 4Q
B5: Momentum | C5: STABLE
D7: Q1-24 | E7: Q2-24 | F7: Q3-24 | G7: Q4-24 | H7: FY24 | I7: Q1-25 | J7: Q2-25 | K7: Q3-25 | L7: Q4-25 | M7: FY25 | N7: Q1-26 | O7: Q2-26E | P7: Q3-26E | Q7: Q4-26E | R7: FY26E | S7: Q1-27E | T7: Q2-27E | U7: Q3-27E | V7: Q4-27E | W7: FY27E | X7: Q1-28E
B9: Total Revenue | D9: 458.002 | E9: 450.561 | F9: 478.109 | G9: 529.375 | H9: =SUM(D9:G9) | I9: 548.398 | J9: 549.014 | K9: 591.402 | L9: 628.309 | M9: =SUM(I9:L9) | N9: 695.072 | O9: =N9+O13 | P9: =O9+P13 | Q9: =P9+Q13 | R9: =SUM(N9:Q9) | S9: =Q9+S13 | T9: =S9+T13 | U9: =T9+U13 | V9: =U9+V13 | W9: =SUM(S9:V9) | X9: =V9+X13
B10: % YoY | I10: =IFERROR((I9-D9)/D9,"-") | J10: =IFERROR((J9-E9)/E9,"-") | K10: =IFERROR((K9-F9)/F9,"-") | L10: =IFERROR((L9-G9)/G9,"-") | M10: =IFERROR((M9-H9)/H9,"-") | N10: =IFERROR((N9-I9)/I9,"-") | O10: =IFERROR((O9-J9)/J9,"-") | P10: =IFERROR((P9-K9)/K9,"-") | ... X10: =IFERROR((X9-S9)/S9,"-")
B11: % QoQ | E11: =IFERROR((E9-D9)/D9,"-") | F11: =IFERROR((F9-E9)/E9,"-") | G11: =IFERROR((G9-F9)/F9,"-") | I11: =IFERROR((I9-G9)/G9,"-") | J11: =IFERROR((J9-I9)/I9,"-") | K11: =IFERROR((K9-J9)/J9,"-") | L11: =IFERROR((L9-K9)/K9,"-") | N11: =IFERROR((N9-L9)/L9,"-") | O11: =IFERROR((O9-N9)/N9,"-") | P11: =IFERROR((P9-O9)/O9,"-") | Q11: =IFERROR((Q9-P9)/P9,"-") | S11: =IFERROR((S9-Q9)/Q9,"-") | T11: =IFERROR((T9-S9)/S9,"-") | U11: =IFERROR((U9-T9)/T9,"-") | V11: =IFERROR((V9-U9)/U9,"-") | X11: =IFERROR((X9-V9)/V9,"-")
B12: $ YoY | I12: =I9-D9 | J12: =J9-E9 | K12: =K9-F9 | L12: =L9-G9 | M12: =M9-H9 | N12: =N9-I9 | O12: =O9-J9 | P12: =P9-K9 | ... X12: =X9-S9
B13: $ QoQ | E13: =E9-D9 | F13: =F9-E9 | G13: =G9-F9 | I13: =I9-G9 | J13: =J9-I9 | K13: =K9-J9 | L13: =L9-K9 | N13: =N9-L9 | O13: -16.574448 | P13: 32.030919 | Q13: 55.52654 | S13: 45.064476 | T13: 10.768684 | U13: 28.598296 | V13: 44.447627 | X13: 45.164744
B15: Consensus Total Revenue | O15: 645.88058 | P15: 695.74741 | Q15: 738.55771 | S15: 796.66081 | T15: 777.20729 | U15: 821.78655 | V15: 867.66845 | W15: =SUM(S15:V15) | X15: 931.85208
B16: % YoY | T16: =IFERROR((T15-O15)/O15,"-") | U16: =IFERROR((U15-P15)/P15,"-") | V16: =IFERROR((V15-Q15)/Q15,"-") | X16: =IFERROR((X15-S15)/S15,"-")
B17: % QoQ | P17: =IFERROR((P15-O15)/O15,"-") | Q17: =IFERROR((Q15-P15)/P15,"-") | S17: =IFERROR((S15-Q15)/Q15,"-") | T17: =IFERROR((T15-S15)/S15,"-") | U17: =IFERROR((U15-T15)/T15,"-") | V17: =IFERROR((V15-U15)/U15,"-") | X17: =IFERROR((X15-V15)/V15,"-")
B18: $ YoY | T18: =T15-O15 | U18: =U15-P15 | V18: =V15-Q15 | X18: =X15-S15
B19: $ QoQ | P19: =P15-O15 | Q19: =Q15-P15 | S19: =S15-Q15 | T19: =T15-S15 | U19: =U15-T15 | V19: =V15-U15 | X19: =X15-V15
B21: % Variance vs Consensus | O21: =IFERROR((O9-O15)/O15,"-") | P21: =IFERROR((P9-P15)/P15,"-") | Q21: =IFERROR((Q9-Q15)/Q15,"-") | R21: =IFERROR((R9-R15)/R15,"-") | S21: =IFERROR((S9-S15)/S15,"-") | T21: =IFERROR((T9-T15)/T15,"-") | U21: =IFERROR((U9-U15)/U15,"-") | V21: =IFERROR((V9-V15)/V15,"-") | ... X21: =IFERROR((X9-X15)/X15,"-")
B23: Implied Q+2 Guide | P23: =P9/(1+$C$3)
B24: % YoY | P24: =IFERROR((P23-K9)/K9,"-")
B25: % QoQ | P25: =IFERROR((P23-O9)/O9,"-")
B26: $ YoY | P26: =P23-K9
B27: $ QoQ | P27: =P23-O9
B29: % Variance Guide vs Consensus | P29: =IFERROR((P23-P15)/P15,"-")
B31: Actuals vs Consensus
B32: Actual Revenue | D32: 458.002 | E32: 450.561 | F32: 478.109 | G32: 529.375 | H32: =SUM(D32:G32) | I32: 548.398 | J32: 549.014 | K32: 591.402 | L32: 628.309 | M32: =SUM(I32:L32) | N32: 695.072
B33: Consensus Revenue | D33: 437.18812 | E33: 441.4411 | F33: 465.02827 | G33: 497.24119 | H33: =SUM(D33:G33) | I33: 520.64589 | J33: 528.12026 | K33: 554.05889 | L33: 593.93326 | M33: =SUM(I33:L33) | N33: 670.0789
B34: Beat / Miss ($) | D34: =D32-D33 | E34: =E32-E33 | F34: =F32-F33 | G34: =G32-G33 | H34: =H32-H33 | I34: =I32-I33 | J34: =J32-J33 | K34: =K32-K33 | ... N34: =N32-N33
B35: Beat / Miss (%) | D35: =IFERROR((D32-D33)/D33,"-") | E35: =IFERROR((E32-E33)/E33,"-") | F35: =IFERROR((F32-F33)/F33,"-") | G35: =IFERROR((G32-G33)/G33,"-") | H35: =IFERROR((H32-H33)/H33,"-") | I35: =IFERROR((I32-I33)/I33,"-") | J35: =IFERROR((J32-J33)/J33,"-") | K35: =IFERROR((K32-K33)/K33,"-") | ... N35: =IFERROR((N32-N33)/N33,"-")
B37: Trailing 4Q Avg Beat | C37: =AVERAGE(J35,K35,L35,N35)
B38: Trailing 8Q Avg Beat | C38: =AVERAGE(E35,F35,G35,I35,J35,K35,L35,N35)
B39: Selected Beat Cadence | C39: 0.0505

Sheet TENB
B1: TENB: KIN Base Case Operating Model
B2: USD in Millions Unless Stated Otherwise
B3: Beat Cadence (%) | C3: 0.0171
B4: Beat Window | C4: 4Q
B5: Momentum | C5: STABLE
D7: Q1-24 | E7: Q2-24 | F7: Q3-24 | G7: Q4-24 | H7: FY24 | I7: Q1-25 | J7: Q2-25 | K7: Q3-25 | L7: Q4-25 | M7: FY25 | N7: Q1-26E | O7: Q2-26E | P7: Q3-26E | Q7: Q4-26E | R7: FY26E | S7: Q1-27E | T7: Q2-27E | U7: Q3-27E | V7: Q4-27E | W7: FY27E
B9: Total Revenue | D9: 215.961 | E9: 221.241 | F9: 227.088 | G9: 235.731 | H9: =SUM(D9:G9) | I9: 239.137 | J9: 247.295 | K9: 252.44 | L9: 260.533 | M9: =SUM(I9:L9) | N9: =L9+N13 | O9: =N9+O13 | P9: =O9+P13 | Q9: =P9+Q13 | R9: =SUM(N9:Q9) | S9: =Q9+S13 | T9: =S9+T13 | U9: =T9+U13 | V9: =U9+V13 | W9: =SUM(S9:V9)
B10: % YoY | I10: =IFERROR((I9-D9)/D9,"-") | J10: =IFERROR((J9-E9)/E9,"-") | K10: =IFERROR((K9-F9)/F9,"-") | L10: =IFERROR((L9-G9)/G9,"-") | M10: =IFERROR((M9-H9)/H9,"-") | N10: =IFERROR((N9-I9)/I9,"-") | O10: =IFERROR((O9-J9)/J9,"-") | P10: =IFERROR((P9-K9)/K9,"-") | ... W10: =IFERROR((W9-R9)/R9,"-")
B11: % QoQ | E11: =IFERROR((E9-D9)/D9,"-") | F11: =IFERROR((F9-E9)/E9,"-") | G11: =IFERROR((G9-F9)/F9,"-") | I11: =IFERROR((I9-G9)/G9,"-") | J11: =IFERROR((J9-I9)/I9,"-") | K11: =IFERROR((K9-J9)/J9,"-") | L11: =IFERROR((L9-K9)/K9,"-") | N11: =IFERROR((N9-L9)/L9,"-") | O11: =IFERROR((O9-N9)/N9,"-") | P11: =IFERROR((P9-O9)/O9,"-") | Q11: =IFERROR((Q9-P9)/P9,"-") | S11: =IFERROR((S9-Q9)/Q9,"-") | T11: =IFERROR((T9-S9)/S9,"-") | U11: =IFERROR((U9-T9)/T9,"-") | V11: =IFERROR((V9-U9)/U9,"-")
B12: $ YoY | I12: =I9-D9 | J12: =J9-E9 | K12: =K9-F9 | L12: =L9-G9 | M12: =M9-H9 | N12: =N9-I9 | O12: =O9-J9 | P12: =P9-K9 | ... W12: =W9-R9
B13: $ QoQ | E13: =E9-D9 | F13: =F9-E9 | G13: =G9-F9 | I13: =I9-G9 | J13: =J9-I9 | K13: =K9-J9 | L13: =L9-K9 | N13: 0.077831 | O13: 11.476605 | P13: 5.937786 | Q13: 7.525493 | S13: 5.499063 | T13: 6.956187 | U13: 6.531518 | V13: 7.330487
B15: Consensus Total Revenue | N15: 256.22931 | O15: 264.9704 | P15: 269.71966 | Q15: 277.69799 | R15: =SUM(N15:Q15) | S15: 278.28426 | T15: 284.18935 | U15: 289.31136 | V15: 297.74696 | W15: =SUM(S15:V15)
B16: % YoY | S16: =IFERROR((S15-N15)/N15,"-") | T16: =IFERROR((T15-O15)/O15,"-") | U16: =IFERROR((U15-P15)/P15,"-") | V16: =IFERROR((V15-Q15)/Q15,"-") | W16: =IFERROR((W15-R15)/R15,"-")
B17: % QoQ | O17: =IFERROR((O15-N15)/N15,"-") | P17: =IFERROR((P15-O15)/O15,"-") | Q17: =IFERROR((Q15-P15)/P15,"-") | S17: =IFERROR((S15-Q15)/Q15,"-") | T17: =IFERROR((T15-S15)/S15,"-") | U17: =IFERROR((U15-T15)/T15,"-") | V17: =IFERROR((V15-U15)/U15,"-")
B18: $ YoY | S18: =S15-N15 | T18: =T15-O15 | U18: =U15-P15 | V18: =V15-Q15 | W18: =W15-R15
B19: $ QoQ | O19: =O15-N15 | P19: =P15-O15 | Q19: =Q15-P15 | S19: =S15-Q15 | T19: =T15-S15 | U19: =U15-T15 | V19: =V15-U15
B21: % Variance vs Consensus | N21: =IFERROR((N9-N15)/N15,"-") | O21: =IFERROR((O9-O15)/O15,"-") | P21: =IFERROR((P9-P15)/P15,"-") | Q21: =IFERROR((Q9-Q15)/Q15,"-") | R21: =IFERROR((R9-R15)/R15,"-") | S21: =IFERROR((S9-S15)/S15,"-") | T21: =IFERROR((T9-T15)/T15,"-") | U21: =IFERROR((U9-U15)/U15,"-") | ... W21: =IFERROR((W9-W15)/W15,"-")
B23: Implied Q+2 Guide | O23: =O9/(1+$C$3)
B24: % YoY | O24: =IFERROR((O23-J9)/J9,"-")
B25: % QoQ | O25: =IFERROR((O23-N9)/N9,"-")
B26: $ YoY | O26: =O23-J9
B27: $ QoQ | O27: =O23-N9
B29: % Variance Guide vs Consensus | O29: =IFERROR((O23-O15)/O15,"-")
B31: Actuals vs Consensus
B32: Actual Revenue | D32: 215.961 | E32: 221.241 | F32: 227.088 | G32: 235.731 | H32: =SUM(D32:G32) | I32: 239.137 | J32: 247.295 | K32: 252.44 | L32: 260.533 | M32: =SUM(I32:L32)
B33: Consensus Revenue | D33: 213.55454 | E33: 218.44 | F33: 231.47 | G33: 232.02464 | H33: =SUM(D33:G33) | I33: 234.02901 | J33: 245.12115 | K33: 251.79071 | L33: 251.7559 | M33: =SUM(I33:L33)
B34: Beat / Miss ($) | D34: =D32-D33 | E34: =E32-E33 | F34: =F32-F33 | G34: =G32-G33 | H34: =H32-H33 | I34: =I32-I33 | J34: =J32-J33 | K34: =K32-K33 | ... M34: =M32-M33
B35: Beat / Miss (%) | D35: =IFERROR((D32-D33)/D33,"-") | E35: =IFERROR((E32-E33)/E33,"-") | F35: =IFERROR((F32-F33)/F33,"-") | G35: =IFERROR((G32-G33)/G33,"-") | H35: =IFERROR((H32-H33)/H33,"-") | I35: =IFERROR((I32-I33)/I33,"-") | J35: =IFERROR((J32-J33)/J33,"-") | K35: =IFERROR((K32-K33)/K33,"-") | ... M35: =IFERROR((M32-M33)/M33,"-")
B37: Trailing 4Q Avg Beat | C37: =AVERAGE(I35,J35,K35,L35)
B38: Trailing 8Q Avg Beat | C38: =AVERAGE(D35,E35,F35,G35,I35,J35,K35,L35)
B39: Selected Beat Cadence | C39: 0.0171

Sheet QLYS
B1: QLYS: KIN Base Case Operating Model
B2: USD in Millions Unless Stated Otherwise
B3: Beat Cadence (%) | C3: 0.0067
B4: Beat Window | C4: 8Q
B5: Momentum | C5: STABLE
D7: Q1-24 | E7: Q2-24 | F7: Q3-24 | G7: Q4-24 | H7: FY24 | I7: Q1-25 | J7: Q2-25 | K7: Q3-25 | L7: Q4-25 | M7: FY25 | N7: Q1-26E | O7: Q2-26E | P7: Q3-26E | Q7: Q4-26E | R7: FY26E | S7: Q1-27E | T7: Q2-27E | U7: Q3-27E | V7: Q4-27E | W7: FY27E
B9: Total Revenue | D9: 145.805 | E9: 148.708 | F9: 153.867 | G9: 159.191 | H9: =SUM(D9:G9) | I9: 159.899 | J9: 164.062 | K9: 169.882 | L9: 175.282 | M9: =SUM(I9:L9) | N9: =L9+N13 | O9: =N9+O13 | P9: =O9+P13 | Q9: =P9+Q13 | R9: =SUM(N9:Q9) | S9: =Q9+S13 | T9: =S9+T13 | U9: =T9+U13 | V9: =U9+V13 | W9: =SUM(S9:V9)
B10: % YoY | I10: =IFERROR((I9-D9)/D9,"-") | J10: =IFERROR((J9-E9)/E9,"-") | K10: =IFERROR((K9-F9)/F9,"-") | L10: =IFERROR((L9-G9)/G9,"-") | M10: =IFERROR((M9-H9)/H9,"-") | N10: =IFERROR((N9-I9)/I9,"-") | O10: =IFERROR((O9-J9)/J9,"-") | P10: =IFERROR((P9-K9)/K9,"-") | ... W10: =IFERROR((W9-R9)/R9,"-")
B11: % QoQ | E11: =IFERROR((E9-D9)/D9,"-") | F11: =IFERROR((F9-E9)/E9,"-") | G11: =IFERROR((G9-F9)/F9,"-") | I11: =IFERROR((I9-G9)/G9,"-") | J11: =IFERROR((J9-I9)/I9,"-") | K11: =IFERROR((K9-J9)/J9,"-") | L11: =IFERROR((L9-K9)/K9,"-") | N11: =IFERROR((N9-L9)/L9,"-") | O11: =IFERROR((O9-N9)/N9,"-") | P11: =IFERROR((P9-O9)/O9,"-") | Q11: =IFERROR((Q9-P9)/P9,"-") | S11: =IFERROR((S9-Q9)/Q9,"-") | T11: =IFERROR((T9-S9)/S9,"-") | U11: =IFERROR((U9-T9)/T9,"-") | V11: =IFERROR((V9-U9)/U9,"-")
B12: $ YoY | I12: =I9-D9 | J12: =J9-E9 | K12: =K9-F9 | L12: =L9-G9 | M12: =M9-H9 | N12: =N9-I9 | O12: =O9-J9 | P12: =P9-K9 | ... W12: =W9-R9
B13: $ QoQ | E13: =E9-D9 | F13: =F9-E9 | G13: =G9-F9 | I13: =I9-G9 | J13: =J9-I9 | K13: =K9-J9 | L13: =L9-K9 | N13: -1.776115 | O13: 5.679536 | P13: 5.66231 | Q13: 5.161078 | S13: 2.506203 | T13: 3.432442 | U13: 4.730111 | V13: 4.927198
B15: Consensus Total Revenue | N15: 172.35113 | O15: 176.83832 | P15: 182.72897 | Q15: 187.88311 | R15: =SUM(N15:Q15) | S15: 187.25783 | T15: 189.99942 | U15: 195.08309 | V15: 199.77008 | W15: =SUM(S15:V15)
B16: % YoY | S16: =IFERROR((S15-N15)/N15,"-") | T16: =IFERROR((T15-O15)/O15,"-") | U16: =IFERROR((U15-P15)/P15,"-") | V16: =IFERROR((V15-Q15)/Q15,"-") | W16: =IFERROR((W15-R15)/R15,"-")
B17: % QoQ | O17: =IFERROR((O15-N15)/N15,"-") | P17: =IFERROR((P15-O15)/O15,"-") | Q17: =IFERROR((Q15-P15)/P15,"-") | S17: =IFERROR((S15-Q15)/Q15,"-") | T17: =IFERROR((T15-S15)/S15,"-") | U17: =IFERROR((U15-T15)/T15,"-") | V17: =IFERROR((V15-U15)/U15,"-")
B18: $ YoY | S18: =S15-N15 | T18: =T15-O15 | U18: =U15-P15 | V18: =V15-Q15 | W18: =W15-R15
B19: $ QoQ | O19: =O15-N15 | P19: =P15-O15 | Q19: =Q15-P15 | S19: =S15-Q15 | T19: =T15-S15 | U19: =U15-T15 | V19: =V15-U15
B21: % Variance vs Consensus | N21: =IFERROR((N9-N15)/N15,"-") | O21: =IFERROR((O9-O15)/O15,"-") | P21: =IFERROR((P9-P15)/P15,"-") | Q21: =IFERROR((Q9-Q15)/Q15,"-") | R21: =IFERROR((R9-R15)/R15,"-") | S21: =IFERROR((S9-S15)/S15,"-") | T21: =IFERROR((T9-T15)/T15,"-") | U21: =IFERROR((U9-U15)/U15,"-") | ... W21: =IFERROR((W9-W15)/W15,"-")
B23: Implied Q+2 Guide | O23: =O9/(1+$C$3)
B24: % YoY | O24: =IFERROR((O23-J9)/J9,"-")
B25: % QoQ | O25: =IFERROR((O23-N9)/N9,"-")
B26: $ YoY | O26: =O23-J9
B27: $ QoQ | O27: =O23-N9
B29: % Variance Guide vs Consensus | O29: =IFERROR((O23-O15)/O15,"-")
B31: Actuals vs Consensus
B32: Actual Revenue | D32: 145.805 | E32: 148.708 | F32: 153.867 | G32: 159.191 | H32: =SUM(D32:G32) | I32: 159.899 | J32: 164.062 | K32: 169.882 | L32: 175.282 | M32: =SUM(I32:L32)
B33: Consensus Revenue | D33: 145.7 | E33: 148.7 | F33: 150.7 | G33: 156.27221 | H33: =SUM(D33:G33) | I33: 159.91182 | J33: 161.26166 | K33: 173.1789 | L33: 173.1643 | M33: =SUM(I33:L33)
B34: Beat / Miss ($) | D34: =D32-D33 | E34: =E32-E33 | F34: =F32-F33 | G34: =G32-G33 | H34: =H32-H33 | I34: =I32-I33 | J34: =J32-J33 | K34: =K32-K33 | ... M34: =M32-M33
B35: Beat / Miss (%) | D35: =IFERROR((D32-D33)/D33,"-") | E35: =IFERROR((E32-E33)/E33,"-") | F35: =IFERROR((F32-F33)/F33,"-") | G35: =IFERROR((G32-G33)/G33,"-") | H35: =IFERROR((H32-H33)/H33,"-") | I35: =IFERROR((I32-I33)/I33,"-") | J35: =IFERROR((J32-J33)/J33,"-") | K35: =IFERROR((K32-K33)/K33,"-") | ... M35: =IFERROR((M32-M33)/M33,"-")
B37: Trailing 4Q Avg Beat | C37: =AVERAGE(I35,J35,K35,L35)
B38: Trailing 8Q Avg Beat | C38: =AVERAGE(D35,E35,F35,G35,I35,J35,K35,L35)
B39: Selected Beat Cadence | C39: 0.0067

Sheet NOW
B1: NOW: KIN Base Case Operating Model
B2: USD in Millions Unless Stated Otherwise
B3: Beat Cadence (%) | C3: 0.0111
B4: Beat Window | C4: 8Q
B5: Momentum | C5: STABLE
D7: Q1-24 | E7: Q2-24 | F7: Q3-24 | G7: Q4-24 | H7: FY24 | I7: Q1-25 | J7: Q2-25 | K7: Q3-25 | L7: Q4-25 | M7: FY25 | N7: Q1-26E | O7: Q2-26E | P7: Q3-26E | Q7: Q4-26E | R7: FY26E | S7: Q1-27E | T7: Q2-27E | U7: Q3-27E | V7: Q4-27E | W7: FY27E
B9: Total Revenue | D9: 2603 | E9: 2627 | F9: 2797 | G9: 2957 | H9: =SUM(D9:G9) | I9: 3088 | J9: 3215 | K9: 3407 | L9: 3568 | M9: =SUM(I9:L9) | N9: =L9+N13 | O9: =N9+O13 | P9: =O9+P13 | Q9: =P9+Q13 | R9: =SUM(N9:Q9) | S9: =Q9+S13 | T9: =S9+T13 | U9: =T9+U13 | V9: =U9+V13 | W9: =SUM(S9:V9)
B10: % YoY | I10: =IFERROR((I9-D9)/D9,"-") | J10: =IFERROR((J9-E9)/E9,"-") | K10: =IFERROR((K9-F9)/F9,"-") | L10: =IFERROR((L9-G9)/G9,"-") | M10: =IFERROR((M9-H9)/H9,"-") | N10: =IFERROR((N9-I9)/I9,"-") | O10: =IFERROR((O9-J9)/J9,"-") | P10: =IFERROR((P9-K9)/K9,"-") | ... W10: =IFERROR((W9-R9)/R9,"-")
B11: % QoQ | E11: =IFERROR((E9-D9)/D9,"-") | F11: =IFERROR((F9-E9)/E9,"-") | G11: =IFERROR((G9-F9)/F9,"-") | I11: =IFERROR((I9-G9)/G9,"-") | J11: =IFERROR((J9-I9)/I9,"-") | K11: =IFERROR((K9-J9)/J9,"-") | L11: =IFERROR((L9-K9)/K9,"-") | N11: =IFERROR((N9-L9)/L9,"-") | O11: =IFERROR((O9-N9)/N9,"-") | P11: =IFERROR((P9-O9)/O9,"-") | Q11: =IFERROR((Q9-P9)/P9,"-") | S11: =IFERROR((S9-Q9)/Q9,"-") | T11: =IFERROR((T9-S9)/S9,"-") | U11: =IFERROR((U9-T9)/T9,"-") | V11: =IFERROR((V9-U9)/U9,"-")
B12: $ YoY | I12: =I9-D9 | J12: =J9-E9 | K12: =K9-F9 | L12: =L9-G9 | M12: =M9-H9 | N12: =N9-I9 | O12: =O9-J9 | P12: =P9-K9 | ... W12: =W9-R9
B13: $ QoQ | E13: =E9-D9 | F13: =F9-E9 | G13: =G9-F9 | I13: =I9-G9 | J13: =J9-I9 | K13: =K9-J9 | L13: =L9-K9 | N13: 190.18823 | O13: 65.303325 | P13: 183.89801 | Q13: 176.59434 | S13: 157.41899 | T13: 151.35684 | U13: 180.50384 | V13: 187.62972
B15: Consensus Total Revenue | N15: 3716.9303 | O15: 3869.7963 | P15: 4087.4178 | Q15: 4284.6214 | R15: =SUM(N15:Q15) | S15: 4435.4827 | T15: 4569.485 | U15: 4817.0298 | V15: 5029.4411 | W15: =SUM(S15:V15)
B16: % YoY | S16: =IFERROR((S15-N15)/N15,"-") | T16: =IFERROR((T15-O15)/O15,"-") | U16: =IFERROR((U15-P15)/P15,"-") | V16: =IFERROR((V15-Q15)/Q15,"-") | W16: =IFERROR((W15-R15)/R15,"-")
B17: % QoQ | O17: =IFERROR((O15-N15)/N15,"-") | P17: =IFERROR((P15-O15)/O15,"-") | Q17: =IFERROR((Q15-P15)/P15,"-") | S17: =IFERROR((S15-Q15)/Q15,"-") | T17: =IFERROR((T15-S15)/S15,"-") | U17: =IFERROR((U15-T15)/T15,"-") | V17: =IFERROR((V15-U15)/U15,"-")
B18: $ YoY | S18: =S15-N15 | T18: =T15-O15 | U18: =U15-P15 | V18: =V15-Q15 | W18: =W15-R15
B19: $ QoQ | O19: =O15-N15 | P19: =P15-O15 | Q19: =Q15-P15 | S19: =S15-Q15 | T19: =T15-S15 | U19: =U15-T15 | V19: =V15-U15
B21: % Variance vs Consensus | N21: =IFERROR((N9-N15)/N15,"-") | O21: =IFERROR((O9-O15)/O15,"-") | P21: =IFERROR((P9-P15)/P15,"-") | Q21: =IFERROR((Q9-Q15)/Q15,"-") | R21: =IFERROR((R9-R15)/R15,"-") | S21: =IFERROR((S9-S15)/S15,"-") | T21: =IFERROR((T9-T15)/T15,"-") | U21: =IFERROR((U9-U15)/U15,"-") | ... W21: =IFERROR((W9-W15)/W15,"-")
B23: Implied Q+2 Guide | O23: =O9/(1+$C$3)
B24: % YoY | O24: =IFERROR((O23-J9)/J9,"-")
B25: % QoQ | O25: =IFERROR((O23-N9)/N9,"-")
B26: $ YoY | O26: =O23-J9
B27: $ QoQ | O27: =O23-N9
B29: % Variance Guide vs Consensus | O29: =IFERROR((O23-O15)/O15,"-")
B31: Actuals vs Consensus
B32: Actual Revenue | D32: 2603 | E32: 2627 | F32: 2797 | G32: 2957 | H32: =SUM(D32:G32) | I32: 3088 | J32: 3215 | K32: 3407 | L32: 3568 | M32: =SUM(I32:L32)
B33: Consensus Revenue | D33: 2588.0855 | E33: 2606.8019 | F33: 2745.5301 | G33: 2963.3053 | H33: =SUM(D33:G33) | I33: 3083.2394 | J33: 3120.4509 | K33: 3355.3464 | L33: 3528.315 | M33: =SUM(I33:L33)
B34: Beat / Miss ($) | D34: =D32-D33 | E34: =E32-E33 | F34: =F32-F33 | G34: =G32-G33 | H34: =H32-H33 | I34: =I32-I33 | J34: =J32-J33 | K34: =K32-K33 | ... M34: =M32-M33
B35: Beat / Miss (%) | D35: =IFERROR((D32-D33)/D33,"-") | E35: =IFERROR((E32-E33)/E33,"-") | F35: =IFERROR((F32-F33)/F33,"-") | G35: =IFERROR((G32-G33)/G33,"-") | H35: =IFERROR((H32-H33)/H33,"-") | I35: =IFERROR((I32-I33)/I33,"-") | J35: =IFERROR((J32-J33)/J33,"-") | K35: =IFERROR((K32-K33)/K33,"-") | ... M35: =IFERROR((M32-M33)/M33,"-")
B37: Trailing 4Q Avg Beat | C37: =AVERAGE(I35,J35,K35,L35)
B38: Trailing 8Q Avg Beat | C38: =AVERAGE(D35,E35,F35,G35,I35,J35,K35,L35)
B39: Selected Beat Cadence | C39: 0.0111

Sheet ADBE
B1: ADBE: KIN Base Case Operating Model
B2: USD in Millions Unless Stated Otherwise
B3: Beat Cadence (%) | C3: 0.0144
B4: Beat Window | C4: 4Q
B5: Momentum | C5: STABLE
D7: Q1-24 | E7: Q2-24 | F7: Q3-24 | G7: Q4-24 | H7: FY24 | I7: Q1-25 | J7: Q2-25 | K7: Q3-25 | L7: Q4-25 | M7: FY25 | N7: Q1-26 | O7: Q2-26E | P7: Q3-26E | Q7: Q4-26E | R7: FY26E | S7: Q1-27E | T7: Q2-27E | U7: Q3-27E | V7: Q4-27E | W7: FY27E
B9: Total Revenue | D9: 5182 | E9: 5309 | F9: 5408 | G9: 5606 | H9: =SUM(D9:G9) | I9: 5714 | J9: 5873 | K9: 5988 | L9: 6194 | M9: =SUM(I9:L9) | N9: 6398 | O9: =N9+O13 | P9: =O9+P13 | Q9: =P9+Q13 | R9: =SUM(N9:Q9) | S9: =Q9+S13 | T9: =S9+T13 | U9: =T9+U13 | V9: =U9+V13 | W9: =SUM(S9:V9)
B10: % YoY | I10: =IFERROR((I9-D9)/D9,"-") | J10: =IFERROR((J9-E9)/E9,"-") | K10: =IFERROR((K9-F9)/F9,"-") | L10: =IFERROR((L9-G9)/G9,"-") | M10: =IFERROR((M9-H9)/H9,"-") | N10: =IFERROR((N9-I9)/I9,"-") | O10: =IFERROR((O9-J9)/J9,"-") | P10: =IFERROR((P9-K9)/K9,"-") | ... W10: =IFERROR((W9-R9)/R9,"-")
B11: % QoQ | E11: =IFERROR((E9-D9)/D9,"-") | F11: =IFERROR((F9-E9)/E9,"-") | G11: =IFERROR((G9-F9)/F9,"-") | I11: =IFERROR((I9-G9)/G9,"-") | J11: =IFERROR((J9-I9)/I9,"-") | K11: =IFERROR((K9-J9)/J9,"-") | L11: =IFERROR((L9-K9)/K9,"-") | N11: =IFERROR((N9-L9)/L9,"-") | O11: =IFERROR((O9-N9)/N9,"-") | P11: =IFERROR((P9-O9)/O9,"-") | Q11: =IFERROR((Q9-P9)/P9,"-") | S11: =IFERROR((S9-Q9)/Q9,"-") | T11: =IFERROR((T9-S9)/S9,"-") | U11: =IFERROR((U9-T9)/T9,"-") | V11: =IFERROR((V9-U9)/U9,"-")
B12: $ YoY | I12: =I9-D9 | J12: =J9-E9 | K12: =K9-F9 | L12: =L9-G9 | M12: =M9-H9 | N12: =N9-I9 | O12: =O9-J9 | P12: =P9-K9 | ... W12: =W9-R9
B13: $ QoQ | E13: =E9-D9 | F13: =F9-E9 | G13: =G9-F9 | I13: =I9-G9 | J13: =J9-I9 | K13: =K9-J9 | L13: =L9-K9 | N13: =N9-L9 | O13: 75.018145 | P13: 118.37264 | Q13: 189.56795 | S13: 198.52024 | T13: 133.78074 | U13: 133.2928 | V13: 170.73877
B15: Consensus Total Revenue | O15: 6381.1299 | P15: 6600.6544 | Q15: 6818.0476 | S15: 6811.84 | T15: 6945.2236 | U15: 7184.1541 | V15: 7420.7649 | W15: =SUM(S15:V15)
B16: % YoY | T16: =IFERROR((T15-O15)/O15,"-") | U16: =IFERROR((U15-P15)/P15,"-") | V16: =IFERROR((V15-Q15)/Q15,"-")
B17: % QoQ | P17: =IFERROR((P15-O15)/O15,"-") | Q17: =IFERROR((Q15-P15)/P15,"-") | S17: =IFERROR((S15-Q15)/Q15,"-") | T17: =IFERROR((T15-S15)/S15,"-") | U17: =IFERROR((U15-T15)/T15,"-") | V17: =IFERROR((V15-U15)/U15,"-")
B18: $ YoY | T18: =T15-O15 | U18: =U15-P15 | V18: =V15-Q15
B19: $ QoQ | P19: =P15-O15 | Q19: =Q15-P15 | S19: =S15-Q15 | T19: =T15-S15 | U19: =U15-T15 | V19: =V15-U15
B21: % Variance vs Consensus | O21: =IFERROR((O9-O15)/O15,"-") | P21: =IFERROR((P9-P15)/P15,"-") | Q21: =IFERROR((Q9-Q15)/Q15,"-") | R21: =IFERROR((R9-R15)/R15,"-") | S21: =IFERROR((S9-S15)/S15,"-") | T21: =IFERROR((T9-T15)/T15,"-") | U21: =IFERROR((U9-U15)/U15,"-") | V21: =IFERROR((V9-V15)/V15,"-") | W21: =IFERROR((W9-W15)/W15,"-")
B23: Implied Q+2 Guide | P23: =P9/(1+$C$3)
B24: % YoY | P24: =IFERROR((P23-K9)/K9,"-")
B25: % QoQ | P25: =IFERROR((P23-O9)/O9,"-")
B26: $ YoY | P26: =P23-K9
B27: $ QoQ | P27: =P23-O9
B29: % Variance Guide vs Consensus | P29: =IFERROR((P23-P15)/P15,"-")
B31: Actuals vs Consensus
B32: Actual Revenue | D32: 5182 | E32: 5309 | F32: 5408 | G32: 5606 | H32: =SUM(D32:G32) | I32: 5714 | J32: 5873 | K32: 5988 | L32: 6194 | M32: =SUM(I32:L32) | N32: 6398
B33: Consensus Revenue | D33: 5143.4329 | E33: 5291.458 | F33: 5371.9684 | G33: 5539.9607 | H33: =SUM(D33:G33) | I33: 5661.5137 | J33: 5799.3273 | K33: 5918.002 | L33: 6110.25 | M33: =SUM(I33:L33) | N33: 6276.514
B34: Beat / Miss ($) | D34: =D32-D33 | E34: =E32-E33 | F34: =F32-F33 | G34: =G32-G33 | H34: =H32-H33 | I34: =I32-I33 | J34: =J32-J33 | K34: =K32-K33 | ... N34: =N32-N33
B35: Beat / Miss (%) | D35: =IFERROR((D32-D33)/D33,"-") | E35: =IFERROR((E32-E33)/E33,"-") | F35: =IFERROR((F32-F33)/F33,"-") | G35: =IFERROR((G32-G33)/G33,"-") | H35: =IFERROR((H32-H33)/H33,"-") | I35: =IFERROR((I32-I33)/I33,"-") | J35: =IFERROR((J32-J33)/J33,"-") | K35: =IFERROR((K32-K33)/K33,"-") | ... N35: =IFERROR((N32-N33)/N33,"-")
B37: Trailing 4Q Avg Beat | C37: =AVERAGE(J35,K35,L35,N35)
B38: Trailing 8Q Avg Beat | C38: =AVERAGE(E35,F35,G35,I35,J35,K35,L35,N35)
B39: Selected Beat Cadence | C39: 0.0144

Sheet INTU
B1: INTU: KIN Base Case Operating Model
B2: USD in Millions Unless Stated Otherwise
B3: Beat Cadence (%) | C3: 0.0271
B4: Beat Window | C4: 4Q
B5: Momentum | C5: ACCELERATING
D7: Q1-24 | E7: Q2-24 | F7: Q3-24 | G7: Q4-24 | H7: FY24 | I7: Q1-25 | J7: Q2-25 | K7: Q3-25 | L7: Q4-25 | M7: FY25 | N7: Q1-26 | O7: Q2-26E | P7: Q3-26E | Q7: Q4-26E | R7: FY26E | S7: Q1-27E | T7: Q2-27E | U7: Q3-27E | V7: Q4-27E | W7: FY27E | X7: Q1-28E
B9: Total Revenue | D9: 3386 | E9: 6737 | F9: 3184 | G9: 3283 | H9: =SUM(D9:G9) | I9: 3963 | J9: 7754 | K9: 3831 | L9: 3885 | M9: =SUM(I9:L9) | N9: 4651 | O9: =N9+O13 | P9: =O9+P13 | Q9: =P9+Q13 | R9: =SUM(N9:Q9) | S9: =Q9+S13 | T9: =S9+T13 | U9: =T9+U13 | V9: =U9+V13 | W9: =SUM(S9:V9) | X9: =V9+X13
B10: % YoY | I10: =IFERROR((I9-D9)/D9,"-") | J10: =IFERROR((J9-E9)/E9,"-") | K10: =IFERROR((K9-F9)/F9,"-") | L10: =IFERROR((L9-G9)/G9,"-") | M10: =IFERROR((M9-H9)/H9,"-") | N10: =IFERROR((N9-I9)/I9,"-") | O10: =IFERROR((O9-J9)/J9,"-") | P10: =IFERROR((P9-K9)/K9,"-") | ... X10: =IFERROR((X9-S9)/S9,"-")
B11: % QoQ | E11: =IFERROR((E9-D9)/D9,"-") | F11: =IFERROR((F9-E9)/E9,"-") | G11: =IFERROR((G9-F9)/F9,"-") | I11: =IFERROR((I9-G9)/G9,"-") | J11: =IFERROR((J9-I9)/I9,"-") | K11: =IFERROR((K9-J9)/J9,"-") | L11: =IFERROR((L9-K9)/K9,"-") | N11: =IFERROR((N9-L9)/L9,"-") | O11: =IFERROR((O9-N9)/N9,"-") | P11: =IFERROR((P9-O9)/O9,"-") | Q11: =IFERROR((Q9-P9)/P9,"-") | S11: =IFERROR((S9-Q9)/Q9,"-") | T11: =IFERROR((T9-S9)/S9,"-") | U11: =IFERROR((U9-T9)/T9,"-") | V11: =IFERROR((V9-U9)/U9,"-") | X11: =IFERROR((X9-V9)/V9,"-")
B12: $ YoY | I12: =I9-D9 | J12: =J9-E9 | K12: =K9-F9 | L12: =L9-G9 | M12: =M9-H9 | N12: =N9-I9 | O12: =O9-J9 | P12: =P9-K9 | ... X12: =X9-S9
B13: $ QoQ | E13: =E9-D9 | F13: =F9-E9 | G13: =G9-F9 | I13: =I9-G9 | J13: =J9-I9 | K13: =K9-J9 | L13: =L9-K9 | N13: =N9-L9 | O13: -437.33714 | P13: 1153.3968 | Q13: -270.64629 | S13: 504.15052 | T13: 2345.1416 | U13: -422.73914 | V13: -11.736672 | X13: 418.81531
B15: Consensus Total Revenue | O15: 4102.4855 | P15: 4911.3668 | Q15: 9204.625 | S15: 4547.7068 | T15: 9404.6443 | U15: 4721.8056 | V15: 5027.0884 | W15: =SUM(S15:V15) | X15: 5872.7955
B16: % YoY | T16: =IFERROR((T15-O15)/O15,"-") | U16: =IFERROR((U15-P15)/P15,"-") | V16: =IFERROR((V15-Q15)/Q15,"-") | X16: =IFERROR((X15-S15)/S15,"-")
B17: % QoQ | P17: =IFERROR((P15-O15)/O15,"-") | Q17: =IFERROR((Q15-P15)/P15,"-") | S17: =IFERROR((S15-Q15)/Q15,"-") | T17: =IFERROR((T15-S15)/S15,"-") | U17: =IFERROR((U15-T15)/T15,"-") | V17: =IFERROR((V15-U15)/U15,"-") | X17: =IFERROR((X15-V15)/V15,"-")
B18: $ YoY | T18: =T15-O15 | U18: =U15-P15 | V18: =V15-Q15 | X18: =X15-S15
B19: $ QoQ | P19: =P15-O15 | Q19: =Q15-P15 | S19: =S15-Q15 | T19: =T15-S15 | U19: =U15-T15 | V19: =V15-U15 | X19: =X15-V15
B21: % Variance vs Consensus | O21: =IFERROR((O9-O15)/O15,"-") | P21: =IFERROR((P9-P15)/P15,"-") | Q21: =IFERROR((Q9-Q15)/Q15,"-") | R21: =IFERROR((R9-R15)/R15,"-") | S21: =IFERROR((S9-S15)/S15,"-") | T21: =IFERROR((T9-T15)/T15,"-") | U21: =IFERROR((U9-U15)/U15,"-") | V21: =IFERROR((V9-V15)/V15,"-") | ... X21: =IFERROR((X9-X15)/X15,"-")
B23: Implied Q+2 Guide | P23: =P9/(1+$C$3)
B24: % YoY | P24: =IFERROR((P23-K9)/K9,"-")
B25: % QoQ | P25: =IFERROR((P23-O9)/O9,"-")
B26: $ YoY | P26: =P23-K9
B27: $ QoQ | P27: =P23-O9
B29: % Variance Guide vs Consensus | P29: =IFERROR((P23-P15)/P15,"-")
B31: Actuals vs Consensus
B32: Actual Revenue | D32: 3386 | E32: 6737 | F32: 3184 | G32: 3283 | H32: =SUM(D32:G32) | I32: 3963 | J32: 7754 | K32: 3831 | L32: 3885 | M32: =SUM(I32:L32) | N32: 4651
B33: Consensus Revenue | D33: 3386.4888 | E33: 6647.6814 | F33: 3084.711 | G33: 3139.9826 | H33: =SUM(D33:G33) | I33: 3834.2737 | J33: 7567.5369 | K33: 3743.4979 | L33: 3756.2923 | M33: =SUM(I33:L33) | N33: 4533.614
B34: Beat / Miss ($) | D34: =D32-D33 | E34: =E32-E33 | F34: =F32-F33 | G34: =G32-G33 | H34: =H32-H33 | I34: =I32-I33 | J34: =J32-J33 | K34: =K32-K33 | ... N34: =N32-N33
B35: Beat / Miss (%) | D35: =IFERROR((D32-D33)/D33,"-") | E35: =IFERROR((E32-E33)/E33,"-") | F35: =IFERROR((F32-F33)/F33,"-") | G35: =IFERROR((G32-G33)/G33,"-") | H35: =IFERROR((H32-H33)/H33,"-") | I35: =IFERROR((I32-I33)/I33,"-") | J35: =IFERROR((J32-J33)/J33,"-") | K35: =IFERROR((K32-K33)/K33,"-") | ... N35: =IFERROR((N32-N33)/N33,"-")
B37: Trailing 4Q Avg Beat | C37: =AVERAGE(J35,K35,L35,N35)
B38: Trailing 8Q Avg Beat | C38: =AVERAGE(E35,F35,G35,I35,J35,K35,L35,N35)
B39: Selected Beat Cadence | C39: 0.0271

Sheet WDAY
B1: WDAY: KIN Base Case Operating Model
B2: USD in Millions Unless Stated Otherwise
B3: Beat Cadence (%) | C3: 0.0046
B4: Beat Window | C4: 8Q
B5: Momentum | C5: STABLE
D7: Q1-24 | E7: Q2-24 | F7: Q3-24 | G7: Q4-24 | H7: FY24 | I7: Q1-25 | J7: Q2-25 | K7: Q3-25 | L7: Q4-25 | M7: FY25 | N7: Q1-26 | O7: Q2-26E | P7: Q3-26E | Q7: Q4-26E | R7: FY26E | S7: Q1-27E | T7: Q2-27E | U7: Q3-27E | V7: Q4-27E | W7: FY27E | X7: Q1-28E
B9: Total Revenue | D9: 1938.014 | E9: 1990 | F9: 2085 | G9: 2160 | H9: =SUM(D9:G9) | I9: 2211 | J9: 2240 | K9: 2348 | L9: 2432 | M9: =SUM(I9:L9) | N9: 2532 | O9: =N9+O13 | P9: =O9+P13 | Q9: =P9+Q13 | R9: =SUM(N9:Q9) | S9: =Q9+S13 | T9: =S9+T13 | U9: =T9+U13 | V9: =U9+V13 | W9: =SUM(S9:V9) | X9: =V9+X13
B10: % YoY | I10: =IFERROR((I9-D9)/D9,"-") | J10: =IFERROR((J9-E9)/E9,"-") | K10: =IFERROR((K9-F9)/F9,"-") | L10: =IFERROR((L9-G9)/G9,"-") | M10: =IFERROR((M9-H9)/H9,"-") | N10: =IFERROR((N9-I9)/I9,"-") | O10: =IFERROR((O9-J9)/J9,"-") | P10: =IFERROR((P9-K9)/K9,"-") | ... X10: =IFERROR((X9-S9)/S9,"-")
B11: % QoQ | E11: =IFERROR((E9-D9)/D9,"-") | F11: =IFERROR((F9-E9)/E9,"-") | G11: =IFERROR((G9-F9)/F9,"-") | I11: =IFERROR((I9-G9)/G9,"-") | J11: =IFERROR((J9-I9)/I9,"-") | K11: =IFERROR((K9-J9)/J9,"-") | L11: =IFERROR((L9-K9)/K9,"-") | N11: =IFERROR((N9-L9)/L9,"-") | O11: =IFERROR((O9-N9)/N9,"-") | P11: =IFERROR((P9-O9)/O9,"-") | Q11: =IFERROR((Q9-P9)/P9,"-") | S11: =IFERROR((S9-Q9)/Q9,"-") | T11: =IFERROR((T9-S9)/S9,"-") | U11: =IFERROR((U9-T9)/T9,"-") | V11: =IFERROR((V9-U9)/U9,"-") | X11: =IFERROR((X9-V9)/V9,"-")
B12: $ YoY | I12: =I9-D9 | J12: =J9-E9 | K12: =K9-F9 | L12: =L9-G9 | M12: =M9-H9 | N12: =N9-I9 | O12: =O9-J9 | P12: =P9-K9 | ... X12: =X9-S9
B13: $ QoQ | E13: =E9-D9 | F13: =F9-E9 | G13: =G9-F9 | I13: =I9-G9 | J13: =J9-I9 | K13: =K9-J9 | L13: =L9-K9 | N13: =N9-L9 | O13: -21.058016 | P13: 111.60542 | Q13: 85.759632 | S13: 93.975722 | T13: 38.348931 | U13: 80.455293 | V13: 84.577863 | X13: 92.568712
B15: Consensus Total Revenue | O15: 2499.4445 | P15: 2619.9535 | Q15: 2708.0278 | S15: 2804.1392 | T15: 2803.4461 | U15: 2918.5167 | V15: 3007.6032 | W15: =SUM(S15:V15) | X15: 3116.7405
B16: % YoY | T16: =IFERROR((T15-O15)/O15,"-") | U16: =IFERROR((U15-P15)/P15,"-") | V16: =IFERROR((V15-Q15)/Q15,"-") | X16: =IFERROR((X15-S15)/S15,"-")
B17: % QoQ | P17: =IFERROR((P15-O15)/O15,"-") | Q17: =IFERROR((Q15-P15)/P15,"-") | S17: =IFERROR((S15-Q15)/Q15,"-") | T17: =IFERROR((T15-S15)/S15,"-") | U17: =IFERROR((U15-T15)/T15,"-") | V17: =IFERROR((V15-U15)/U15,"-") | X17: =IFERROR((X15-V15)/V15,"-")
B18: $ YoY | T18: =T15-O15 | U18: =U15-P15 | V18: =V15-Q15 | X18: =X15-S15
B19: $ QoQ | P19: =P15-O15 | Q19: =Q15-P15 | S19: =S15-Q15 | T19: =T15-S15 | U19: =U15-T15 | V19: =V15-U15 | X19: =X15-V15
B21: % Variance vs Consensus | O21: =IFERROR((O9-O15)/O15,"-") | P21: =IFERROR((P9-P15)/P15,"-") | Q21: =IFERROR((Q9-Q15)/Q15,"-") | R21: =IFERROR((R9-R15)/R15,"-") | S21: =IFERROR((S9-S15)/S15,"-") | T21: =IFERROR((T9-T15)/T15,"-") | U21: =IFERROR((U9-U15)/U15,"-") | V21: =IFERROR((V9-V15)/V15,"-") | ... X21: =IFERROR((X9-X15)/X15,"-")
B23: Implied Q+2 Guide | P23: =P9/(1+$C$3)
B24: % YoY | P24: =IFERROR((P23-K9)/K9,"-")
B25: % QoQ | P25: =IFERROR((P23-O9)/O9,"-")
B26: $ YoY | P26: =P23-K9
B27: $ QoQ | P27: =P23-O9
B29: % Variance Guide vs Consensus | P29: =IFERROR((P23-P15)/P15,"-")
B31: Actuals vs Consensus
B32: Actual Revenue | D32: 1938.014 | E32: 1990 | F32: 2085 | G32: 2160 | H32: =SUM(D32:G32) | I32: 2211 | J32: 2240 | K32: 2348 | L32: 2432 | M32: =SUM(I32:L32) | N32: 2532
B33: Consensus Revenue | D33: 1916.7385 | E33: 1975.9166 | F33: 2072.0996 | G33: 2138.3684 | H33: =SUM(D33:G33) | I33: 2183.9355 | J33: 2217.7318 | K33: 2341.4511 | L33: 2417.0925 | M33: =SUM(I33:L33) | N33: 2523.734
B34: Beat / Miss ($) | D34: =D32-D33 | E34: =E32-E33 | F34: =F32-F33 | G34: =G32-G33 | H34: =H32-H33 | I34: =I32-I33 | J34: =J32-J33 | K34: =K32-K33 | ... N34: =N32-N33
B35: Beat / Miss (%) | D35: =IFERROR((D32-D33)/D33,"-") | E35: =IFERROR((E32-E33)/E33,"-") | F35: =IFERROR((F32-F33)/F33,"-") | G35: =IFERROR((G32-G33)/G33,"-") | H35: =IFERROR((H32-H33)/H33,"-") | I35: =IFERROR((I32-I33)/I33,"-") | J35: =IFERROR((J32-J33)/J33,"-") | K35: =IFERROR((K32-K33)/K33,"-") | ... N35: =IFERROR((N32-N33)/N33,"-")
B37: Trailing 4Q Avg Beat | C37: =AVERAGE(J35,K35,L35,N35)
B38: Trailing 8Q Avg Beat | C38: =AVERAGE(E35,F35,G35,I35,J35,K35,L35,N35)
B39: Selected Beat Cadence | C39: 0.0046

Sheet PANW
B1: PANW: KIN Base Case Operating Model
B2: USD in Millions Unless Stated Otherwise
B3: Beat Cadence (%) | C3: 0.0077
B4: Beat Window | C4: 8Q
B5: Momentum | C5: STABLE
D7: Q1-24 | E7: Q2-24 | F7: Q3-24 | G7: Q4-24 | H7: FY24 | I7: Q1-25 | J7: Q2-25 | K7: Q3-25 | L7: Q4-25 | M7: FY25 | N7: Q1-26 | O7: Q2-26E | P7: Q3-26E | Q7: Q4-26E | R7: FY26E | S7: Q1-27E | T7: Q2-27E | U7: Q3-27E | V7: Q4-27E | W7: FY27E | X7: Q1-28E
B9: Total Revenue | D9: 1975.1 | E9: 1984.8 | F9: 2189.5 | G9: 2139 | H9: =SUM(D9:G9) | I9: 2257.4 | J9: 2289 | K9: 2536.1 | L9: 2474 | M9: =SUM(I9:L9) | N9: 2594 | O9: =N9+O13 | P9: =O9+P13 | Q9: =P9+Q13 | R9: =SUM(N9:Q9) | S9: =Q9+S13 | T9: =S9+T13 | U9: =T9+U13 | V9: =U9+V13 | W9: =SUM(S9:V9) | X9: =V9+X13
B10: % YoY | I10: =IFERROR((I9-D9)/D9,"-") | J10: =IFERROR((J9-E9)/E9,"-") | K10: =IFERROR((K9-F9)/F9,"-") | L10: =IFERROR((L9-G9)/G9,"-") | M10: =IFERROR((M9-H9)/H9,"-") | N10: =IFERROR((N9-I9)/I9,"-") | O10: =IFERROR((O9-J9)/J9,"-") | P10: =IFERROR((P9-K9)/K9,"-") | ... X10: =IFERROR((X9-S9)/S9,"-")
B11: % QoQ | E11: =IFERROR((E9-D9)/D9,"-") | F11: =IFERROR((F9-E9)/E9,"-") | G11: =IFERROR((G9-F9)/F9,"-") | I11: =IFERROR((I9-G9)/G9,"-") | J11: =IFERROR((J9-I9)/I9,"-") | K11: =IFERROR((K9-J9)/J9,"-") | L11: =IFERROR((L9-K9)/K9,"-") | N11: =IFERROR((N9-L9)/L9,"-") | O11: =IFERROR((O9-N9)/N9,"-") | P11: =IFERROR((P9-O9)/O9,"-") | Q11: =IFERROR((Q9-P9)/P9,"-") | S11: =IFERROR((S9-Q9)/Q9,"-") | T11: =IFERROR((T9-S9)/S9,"-") | U11: =IFERROR((U9-T9)/T9,"-") | V11: =IFERROR((V9-U9)/U9,"-") | X11: =IFERROR((X9-V9)/V9,"-")
B12: $ YoY | I12: =I9-D9 | J12: =J9-E9 | K12: =K9-F9 | L12: =L9-G9 | M12: =M9-H9 | N12: =N9-I9 | O12: =O9-J9 | P12: =P9-K9 | ... X12: =X9-S9
B13: $ QoQ | E13: =E9-D9 | F13: =F9-E9 | G13: =G9-F9 | I13: =I9-G9 | J13: =J9-I9 | K13: =K9-J9 | L13: =L9-K9 | N13: =N9-L9 | O13: 372.71091 | P13: -128.66279 | Q13: 3.456969 | S13: 88.923583 | T13: 57.668744 | U13: 148.46427 | V13: 68.151396 | X13: 92.590817
B15: Consensus Total Revenue | O15: 2944.0418 | P15: 3276.8422 | Q15: 3165.1649 | S15: 3288.8259 | T15: 3368.9351 | U15: 3693.5538 | V15: 3603.6352 | W15: =SUM(S15:V15) | X15: 3746.122
B16: % YoY | T16: =IFERROR((T15-O15)/O15,"-") | U16: =IFERROR((U15-P15)/P15,"-") | V16: =IFERROR((V15-Q15)/Q15,"-") | X16: =IFERROR((X15-S15)/S15,"-")
B17: % QoQ | P17: =IFERROR((P15-O15)/O15,"-") | Q17: =IFERROR((Q15-P15)/P15,"-") | S17: =IFERROR((S15-Q15)/Q15,"-") | T17: =IFERROR((T15-S15)/S15,"-") | U17: =IFERROR((U15-T15)/T15,"-") | V17: =IFERROR((V15-U15)/U15,"-") | X17: =IFERROR((X15-V15)/V15,"-")
B18: $ YoY | T18: =T15-O15 | U18: =U15-P15 | V18: =V15-Q15 | X18: =X15-S15
B19: $ QoQ | P19: =P15-O15 | Q19: =Q15-P15 | S19: =S15-Q15 | T19: =T15-S15 | U19: =U15-T15 | V19: =V15-U15 | X19: =X15-V15
B21: % Variance vs Consensus | O21: =IFERROR((O9-O15)/O15,"-") | P21: =IFERROR((P9-P15)/P15,"-") | Q21: =IFERROR((Q9-Q15)/Q15,"-") | R21: =IFERROR((R9-R15)/R15,"-") | S21: =IFERROR((S9-S15)/S15,"-") | T21: =IFERROR((T9-T15)/T15,"-") | U21: =IFERROR((U9-U15)/U15,"-") | V21: =IFERROR((V9-V15)/V15,"-") | ... X21: =IFERROR((X9-X15)/X15,"-")
B23: Implied Q+2 Guide | P23: =P9/(1+$C$3)
B24: % YoY | P24: =IFERROR((P23-K9)/K9,"-")
B25: % QoQ | P25: =IFERROR((P23-O9)/O9,"-")
B26: $ YoY | P26: =P23-K9
B27: $ QoQ | P27: =P23-O9
B29: % Variance Guide vs Consensus | P29: =IFERROR((P23-P15)/P15,"-")
B31: Actuals vs Consensus
B32: Actual Revenue | D32: 1975.1 | E32: 1984.8 | F32: 2189.5 | G32: 2139 | H32: =SUM(D32:G32) | I32: 2257.4 | J32: 2289 | K32: 2536.1 | L32: 2474 | M32: =SUM(I32:L32) | N32: 2594
B33: Consensus Revenue | D33: 1970.9749 | E33: 1973.7388 | F33: 2162.3832 | G33: 2120.9182 | H33: =SUM(D33:G33) | I33: 2241.4817 | J33: 2279.1423 | K33: 2501.4913 | L33: 2461.7431 | M33: =SUM(I33:L33) | N33: 2582.811
B34: Beat / Miss ($) | D34: =D32-D33 | E34: =E32-E33 | F34: =F32-F33 | G34: =G32-G33 | H34: =H32-H33 | I34: =I32-I33 | J34: =J32-J33 | K34: =K32-K33 | ... N34: =N32-N33
B35: Beat / Miss (%) | D35: =IFERROR((D32-D33)/D33,"-") | E35: =IFERROR((E32-E33)/E33,"-") | F35: =IFERROR((F32-F33)/F33,"-") | G35: =IFERROR((G32-G33)/G33,"-") | H35: =IFERROR((H32-H33)/H33,"-") | I35: =IFERROR((I32-I33)/I33,"-") | J35: =IFERROR((J32-J33)/J33,"-") | K35: =IFERROR((K32-K33)/K33,"-") | ... N35: =IFERROR((N32-N33)/N33,"-")
B37: Trailing 4Q Avg Beat | C37: =AVERAGE(J35,K35,L35,N35)
B38: Trailing 8Q Avg Beat | C38: =AVERAGE(E35,F35,G35,I35,J35,K35,L35,N35)
B39: Selected Beat Cadence | C39: 0.0077

Sheet CDNS
B1: CDNS: KIN Base Case Operating Model
B2: USD in Millions Unless Stated Otherwise
B3: Beat Cadence (%) | C3: 0.0115
B4: Beat Window | C4: 4Q
B5: Momentum | C5: ACCELERATING
D7: Q1-24 | E7: Q2-24 | F7: Q3-24 | G7: Q4-24 | H7: FY24 | I7: Q1-25 | J7: Q2-25 | K7: Q3-25 | L7: Q4-25 | M7: FY25 | N7: Q1-26E | O7: Q2-26E | P7: Q3-26E | Q7: Q4-26E | R7: FY26E | S7: Q1-27E | T7: Q2-27E | U7: Q3-27E | V7: Q4-27E | W7: FY27E
B9: Total Revenue | D9: 1009.103 | E9: 1060.681 | F9: 1215.499 | G9: 1355.981 | H9: =SUM(D9:G9) | I9: 1242.366 | J9: 1275.441 | K9: 1338.838 | L9: 1440.114 | M9: =SUM(I9:L9) | N9: =L9+N13 | O9: =N9+O13 | P9: =O9+P13 | Q9: =P9+Q13 | R9: =SUM(N9:Q9) | S9: =Q9+S13 | T9: =S9+T13 | U9: =T9+U13 | V9: =U9+V13 | W9: =SUM(S9:V9)
B10: % YoY | I10: =IFERROR((I9-D9)/D9,"-") | J10: =IFERROR((J9-E9)/E9,"-") | K10: =IFERROR((K9-F9)/F9,"-") | L10: =IFERROR((L9-G9)/G9,"-") | M10: =IFERROR((M9-H9)/H9,"-") | N10: =IFERROR((N9-I9)/I9,"-") | O10: =IFERROR((O9-J9)/J9,"-") | P10: =IFERROR((P9-K9)/K9,"-") | ... W10: =IFERROR((W9-R9)/R9,"-")
B11: % QoQ | E11: =IFERROR((E9-D9)/D9,"-") | F11: =IFERROR((F9-E9)/E9,"-") | G11: =IFERROR((G9-F9)/F9,"-") | I11: =IFERROR((I9-G9)/G9,"-") | J11: =IFERROR((J9-I9)/I9,"-") | K11: =IFERROR((K9-J9)/J9,"-") | L11: =IFERROR((L9-K9)/K9,"-") | N11: =IFERROR((N9-L9)/L9,"-") | O11: =IFERROR((O9-N9)/N9,"-") | P11: =IFERROR((P9-O9)/O9,"-") | Q11: =IFERROR((Q9-P9)/P9,"-") | S11: =IFERROR((S9-Q9)/Q9,"-") | T11: =IFERROR((T9-S9)/S9,"-") | U11: =IFERROR((U9-T9)/T9,"-") | V11: =IFERROR((V9-U9)/U9,"-")
B12: $ YoY | I12: =I9-D9 | J12: =J9-E9 | K12: =K9-F9 | L12: =L9-G9 | M12: =M9-H9 | N12: =N9-I9 | O12: =O9-J9 | P12: =P9-K9 | ... W12: =W9-R9
B13: $ QoQ | E13: =E9-D9 | F13: =F9-E9 | G13: =G9-F9 | I13: =I9-G9 | J13: =J9-I9 | K13: =K9-J9 | L13: =L9-K9 | N13: -10.886766 | O13: 23.646159 | P13: 60.097409 | Q13: 86.077312 | S13: 26.917288 | T13: 35.659281 | U13: 51.919998 | V13: 71.468816
B15: Consensus Total Revenue | N15: 1412.978 | O15: 1450.5951 | P15: 1519.6126 | Q15: 1604.5417 | R15: =SUM(N15:Q15) | S15: 1577.0089 | T15: 1621.267 | U15: 1704.2455 | V15: 1825.592 | W15: =SUM(S15:V15)
B16: % YoY | S16: =IFERROR((S15-N15)/N15,"-") | T16: =IFERROR((T15-O15)/O15,"-") | U16: =IFERROR((U15-P15)/P15,"-") | V16: =IFERROR((V15-Q15)/Q15,"-") | W16: =IFERROR((W15-R15)/R15,"-")
B17: % QoQ | O17: =IFERROR((O15-N15)/N15,"-") | P17: =IFERROR((P15-O15)/O15,"-") | Q17: =IFERROR((Q15-P15)/P15,"-") | S17: =IFERROR((S15-Q15)/Q15,"-") | T17: =IFERROR((T15-S15)/S15,"-") | U17: =IFERROR((U15-T15)/T15,"-") | V17: =IFERROR((V15-U15)/U15,"-")
B18: $ YoY | S18: =S15-N15 | T18: =T15-O15 | U18: =U15-P15 | V18: =V15-Q15 | W18: =W15-R15
B19: $ QoQ | O19: =O15-N15 | P19: =P15-O15 | Q19: =Q15-P15 | S19: =S15-Q15 | T19: =T15-S15 | U19: =U15-T15 | V19: =V15-U15
B21: % Variance vs Consensus | N21: =IFERROR((N9-N15)/N15,"-") | O21: =IFERROR((O9-O15)/O15,"-") | P21: =IFERROR((P9-P15)/P15,"-") | Q21: =IFERROR((Q9-Q15)/Q15,"-") | R21: =IFERROR((R9-R15)/R15,"-") | S21: =IFERROR((S9-S15)/S15,"-") | T21: =IFERROR((T9-T15)/T15,"-") | U21: =IFERROR((U9-U15)/U15,"-") | ... W21: =IFERROR((W9-W15)/W15,"-")
B23: Implied Q+2 Guide | O23: =O9/(1+$C$3)
B24: % YoY | O24: =IFERROR((O23-J9)/J9,"-")
B25: % QoQ | O25: =IFERROR((O23-N9)/N9,"-")
B26: $ YoY | O26: =O23-J9
B27: $ QoQ | O27: =O23-N9
B29: % Variance Guide vs Consensus | O29: =IFERROR((O23-O15)/O15,"-")
B31: Actuals vs Consensus
B32: Actual Revenue | D32: 1009.103 | E32: 1060.681 | F32: 1215.499 | G32: 1355.981 | H32: =SUM(D32:G32) | I32: 1242.366 | J32: 1275.441 | K32: 1338.838 | L32: 1440.114 | M32: =SUM(I32:L32)
B33: Consensus Revenue | D33: 1002.2529 | E33: 1042.5777 | F33: 1181.212 | G33: 1345.9122 | H33: =SUM(D33:G33) | I33: 1239.8494 | J33: 1249.9607 | K33: 1322.8618 | L33: 1423.84 | M33: =SUM(I33:L33)
B34: Beat / Miss ($) | D34: =D32-D33 | E34: =E32-E33 | F34: =F32-F33 | G34: =G32-G33 | H34: =H32-H33 | I34: =I32-I33 | J34: =J32-J33 | K34: =K32-K33 | ... M34: =M32-M33
B35: Beat / Miss (%) | D35: =IFERROR((D32-D33)/D33,"-") | E35: =IFERROR((E32-E33)/E33,"-") | F35: =IFERROR((F32-F33)/F33,"-") | G35: =IFERROR((G32-G33)/G33,"-") | H35: =IFERROR((H32-H33)/H33,"-") | I35: =IFERROR((I32-I33)/I33,"-") | J35: =IFERROR((J32-J33)/J33,"-") | K35: =IFERROR((K32-K33)/K33,"-") | ... M35: =IFERROR((M32-M33)/M33,"-")
B37: Trailing 4Q Avg Beat | C37: =AVERAGE(I35,J35,K35,L35)
B38: Trailing 8Q Avg Beat | C38: =AVERAGE(D35,E35,F35,G35,I35,J35,K35,L35)
B39: Selected Beat Cadence | C39: 0.0115

Sheet SNPS
B1: SNPS: KIN Base Case Operating Model
B2: USD in Millions Unless Stated Otherwise
B3: Beat Cadence (%) | C3: 0.002
B4: Beat Window | C4: 8Q
B5: Momentum | C5: STABLE
D7: Q1-24 | E7: Q2-24 | F7: Q3-24 | G7: Q4-24 | H7: FY24 | I7: Q1-25 | J7: Q2-25 | K7: Q3-25 | L7: Q4-25 | M7: FY25 | N7: Q1-26 | O7: Q2-26E | P7: Q3-26E | Q7: Q4-26E | R7: FY26E | S7: Q1-27E | T7: Q2-27E | U7: Q3-27E | V7: Q4-27E | W7: FY27E | X7: Q1-28E
